Workbook

Sheet 安装及设备购置费四厂对比表
A1: 安装及设备购置费四厂对比表
A2: 序号 | B2: 工程或费用名称 | C2: 南站水厂 | I2: 环城北金额 | K2: 洛溪厂（首期） | M2: 中部大龙水厂金额 | O2: 偏差原因分析
C3: 首期 | E3: 二期预估 | G3: 总厂
C4: 安装费 （万元） | D4: 设备购置费 （万元） | E4: 安装费 （万元） | F4: 设备购置费 （万元） | G4: 安装费 （万元） | H4: 设备购置费 （万元） | I4: 安装费 （万元） | J4: 设备购置费 （万元） | K4: 安装费 （万元） | L4: 设备购置费 （万元） | M4: 安装费 （万元） | N4: 设备购置费 （万元）
B5: 污水处理规模（万吨/日） | C5: 5 | E5: 5 | G5: 10 | I5: 10 | K5: 5 | M5: 10
B6: 工艺 | C6: AAO+MBR | I6: AAO+MBR | K6: AAO+MBR | M6: A/A/O-AO
B7: K设计 | C7: 1.5 | I7: 1.5 | K7: 1.3 | M7: 1.5
B8: 安装专业工程费用 | C8: ==C9+C20+C42 -> 4363.3216 | D8: ==D9+D20+D42 -> 13067.646 | E8: ==E9+E20+E42 -> 525.07221 | F8: ==F9+F20+F42 -> 7780.2228 | G8: ==G9+G20+G42 -> 4888.3938 | H8: ==H9+H20+H42 -> 20847.869 | I8: ==I9+I20+I42 -> 7656.68 | J8: ==J9+J20+J42 -> 20780.036 | ... N8: ==N9+N20+N42 -> 15425.084
A9: (一) | B9: 南站水厂的甲供设备部分 | C9: ==SUM(C10:C19) -> 0 | D9: ==SUM(D10:D19) -> 8933.8691 | E9: ==SUM(E10:E19) -> 0 | F9: ==SUM(F10:F19) -> 6308.7907 | G9: ==SUM(G10:G19) -> 0 | H9: ==SUM(H10:H19) -> 15242.66 | I9: ==SUM(I10:I19) -> 985.62 | J9: ==SUM(J10:J19) -> 12014.446 | ... L9: ==SUM(L10:L19) -> 7934.4139 | N9: ==SUM(N10:N19) -> 5879.6848
A10: 1 | B10: 提升泵及配套设备 （首期66%、远期34%） | C10: 0 | D10: ==甲供设备!L6/10000 -> 170.33371 | E10: 0 | F10: ==甲供设备!L7/10000 -> 99.954838 | G10: 0 | H10: ==D10+F10 -> 270.28855 | I10: 0 | J10: ==甲供设备!N6/10000 -> 114.9012 | K10: 0 | L10: ==甲供设备!R6/10000 -> 136.5891 | M10: / | N10: ==甲供设备!P6/10000 -> 220 | O10: 环城北：3台（Q=1300m3/h,H=25m）； 南站水厂：6台（4台Q=2083m3/h，H=9.5m、2台Q=1041m3/h，H=9.5m）； 中部净水厂：5台（Q=1565m3/h，H=9.0m） 洛溪首期：5台（3台Q=1460m3/h，H=6.0m、2台Q=1880m3/h，H=6.0m）； 结论：1、经对比分析，“南站”、“洛溪”和“中部”设备配置及价值水平基本一致； 2、“环城北”水泵设置在放空泵房，水泵投入数量、过水量偏差太大，不具备可比性。 | Q10: 近期4台，远期安装2台
A11: 2 | B11: 内进流格栅除污机及其配套设备 （首期66%、远期34%） | C11: 0 | D11: ==甲供设备!L9/10000 -> 400.72796 | E11: 0 | F11: ==甲供设备!K10/10000+甲供设备!K15*2/10000 -> 207.02453 | G11: 0 | H11: ==D11+F11 -> 607.75249 | I11: 0 | J11: ==甲供设备!N9/10000 -> 569.66 | K11: 0 | L11: ==甲供设备!R9/10000 -> 718.4068 | M11: / | N11: ==甲供设备!P9/10000 -> 510 | O11: 环城北：5套细格栅（Q=1565m3/h，b=5mm）+5套膜格栅（Q=1565m3/h，b=1mm）； 南站水厂：4套细格栅（Q≥2100m3/h，b=5mm）+5膜格栅（Q≥1580m3/h，b=1mm）； 中部净水厂：3套细格栅（Q=3125m3/h，b=6mm）+4膜格栅（Q=2100m3/h，b=2mm） 洛溪首期：3套细格栅（Q=2917m3/h，b=3mm）+3套膜格栅（Q=1436m3/h，b=1mm）； 结论：1、膜格栅：“南站水厂”与“环城北”选用品牌档次不一致，价格水平不具备可比性。 2、经对比分析，“南站水厂”与“中部水厂”设备配置及价值水平基本一致。 | P11: 膜格栅：洛溪用的品牌都是进口的 | Q11: 细格栅近期3台，远期安装1台；膜格栅近期3台，远期安装2台
A12: 3 | B12: 立式搅拌器及配套设备 （首期50%、远期50%） | C12: 0 | D12: ==甲供设备!L20/10000 -> 100.77875 | E12: 0 | F12: ==甲供设备!L20/5*4/10000 -> 80.623 | G12: 0 | H12: ==D12+F12 -> 181.40175 | I12: 0 | J12: ==甲供设备!N20/10000 -> 165 | K12: 0 | L12: ==甲供设备!R20/10000 -> 124.839 | M12: / | N12: ==甲供设备!P20/10000 -> 69 | O12: 环城北：30台潜水搅拌器（D=580mm）+26台潜水推进器（D=2500mm）； 南站水厂：9台潜水搅拌器（D=4000mm）+9台潜水推流器； 中部净水厂：6台潜水搅拌器（D=650mm）+16台潜水推流器； 洛溪首期：15台潜水搅拌器+3台潜水推进器； 结论：经过对比分析，“南站水厂”、“中部水厂”及“环城北”在设备投入数量、规格参数上都不具备可比性。 | Q12: 近期5台（4用1库备），远期4台
A13: 4 | B13: 潜水推流器及配套设备 （首期50%、远期50%） | C13: 0 | D13: ==甲供设备!L23/10000 -> 60.0838 | E13: 0 | F13: ==甲供设备!L23/5*4/10000 -> 48.06704 | G13: 0 | H13: ==D13+F13 -> 108.15084 | I13: 0 | J13: ==甲供设备!N23/10000 -> 221 | K13: 0 | L13: ==甲供设备!R23/10000 -> 33.465 | M13: / | N13: ==甲供设备!P23/10000 -> 216 | Q13: 近期5台（4用1库备），远期4台
A14: 5 | B14: MBR膜池工艺系统及配套设备 （首期50%、远期50%） | D14: ==甲供设备!L25/10000 -> 3305.5671 | F14: ==甲供设备!L25/10000 -> 3305.5671 | H14: ==D14+F14 -> 6611.1341 | I14: 850.44 | J14: 5468.37 | K14: 226.96 | L14: 2371.45 | M14: / | N14: ==甲供设备!P25 -> / | Q14: 近期1座，远期1座
A15: 6 | B15: 精确曝气系统及配套设备 （首期85%、远期15%） | C15: 0 | D15: ==甲供设备!L147/10000 -> 350.33526 | E15: 0 | F15: 50 | G15: 0 | H15: ==D15+F15 -> 400.33526 | I15: 0 | J15: ==甲供设备!N147/10000 -> 554.2 | K15: / | L15: ==甲供设备!R147 -> / | M15: / | N15: ==甲供设备!P147/10000 -> 314.68476 | Q15: 近期4台，远期4台
A16: 7 | B16: 鼓风机及配套设备 （首期50%、远期50%） | C16: 0 | D16: ==甲供设备!L159/10000 -> 909.9395 | E16: 0 | F16: ==甲供设备!L159/10000 -> 909.9395 | G16: 0 | H16: ==D16+F16 -> 1819.879 | I16: 0 | J16: ==甲供设备!N159/10000 -> 1143.22 | K16: 0 | L16: ==甲供设备!R159/10000 -> 1211.8 | M16: / | N16: ==甲供设备!P159/10000 -> 720 | O16: 环城北：2台（Q=4800m3/h）+3台（Q=6600m3/h）+3台（Q=15600m3/h）； 南站水厂：6台（Q=5040m3/h）+6台（Q=7500m3/h）； 中部净水厂：4台（Q=7200m3/h） 洛溪首期：2台（Q=4500m3/h）+1台（Q=9000m3/h）+3台（Q=8940-11880m3/h）； 结论：经过对比分析，“南站水厂”、“中部水厂”及“环城北”在设备投入数量、规格参数上都不具备可比性。 | Q16: 近期3台（2用1备），远期3台
A17: 8 | B17: 污泥装置设备 （首期66%、远期34%） | D17: ==甲供设备!L163/10000 -> 3215.2295 | F17: ==甲供设备!L163/2/10000 -> 1607.6147 | H17: ==D17+F17 -> 4822.8443 | I17: 135.18 | J17: 3349.07 | K17: 432.59 | L17: 3217.44 | M17: / | N17: ==甲供设备!P163/10000 -> 3720 | O17: 环城北：2套干化主机（土建预留1套设备不安装）； 南站水厂：3套干化主机； 中部水厂：3套干化主机； 洛溪首期：2套干化主机； 结论：设备数量不一致，设备价值水平基本一致。 | Q17: 近期2台，远期1台
A18: 9 | B18: 在线仪表设备 （首期100%） | D18: ==甲供设备!L263/10000 -> 120.8736 | F18: 0 | H18: ==D18+F18 -> 120.8736 | I18: 0 | J18: ==甲供设备!N263/10000 -> 104.8 | L18: ==甲供设备!R263/10000 -> 120.424 | M18: / | N18: ==甲供设备!P263/10000 -> 110
A19: 10 | B19: 智慧水厂及配套设备 （首期100%） | D19: ==甲供设备!L270/10000 -> 300 | F19: 0 | H19: ==D19+F19 -> 300 | I19: 0 | J19: ==甲供设备!N270/10000 -> 324.2251 | L19: ==甲供设备!R270 -> / | M19: / | N19: ==甲供设备!P270 -> / | O19: 环城北该项金额是为对应南站水厂的范围剥离出来的金额
A20: （二） | B20: 南站水厂的乙供设备部分 | C20: ==SUM(C21,C34,C35,C36,C39,C40,C41) -> 4363.3216 | D20: ==SUM(D21,D34,D35,D36,D39,D40,D41) -> 4133.7766 | E20: ==SUM(E21,E34,E35,E36,E39,E40,E41) -> 525.07221 | F20: ==SUM(F21,F34,F35,F36,F39,F40,F41) -> 1471.4321 | G20: ==SUM(G21,G34,G35,G36,G39,G40,G41) -> 4888.3938 | H20: ==SUM(H21,H34,H35,H36,H39,H40,H41) -> 5605.2087 | I20: ==SUM(I21,I34,I35,I36,I39,I40,I41) -> 6671.06 | J20: ==SUM(J21,J34,J35,J36,J39,J40,J41) -> 8557.79 | ... N20: ==SUM(N21,N34,N35,N36,N39,N40,N41) -> 9545.3993
A21: 1 | B21: 工艺专业 （首期60%、远期40%） | C21: ==SUM(C22:C33) -> 800.17 | D21: ==SUM(D22:D33) -> 1603.58 | E21: ==SUM(E22:E33) -> 86.462206 | F21: ==SUM(F22:F33) -> 864.62206 | G21: ==SUM(G22:G33) -> 886.63221 | H21: ==SUM(H22:H33) -> 2468.2021 | I21: ==SUM(I22:I33) -> 1412.15 | J21: ==SUM(J22:J33) -> 3078.16 | ... N21: ==SUM(N22:N33) -> 5866.5337 | O21: 偏差原因： 一、设备购置费 1、中部水厂： （1）工艺不同：中部水厂是含高效沉淀池和二沉池系统，南部水厂是膜系统； （2）中部水厂含精细格栅系统，而南部水厂无此系统； （3）中部水厂加药间甲供设备； （4）中部水厂出水及消毒区含精密过滤系统。 2、环城北： （1）南站水厂预处理区格栅系统甲供设备。 （2）南站水厂加药间系统乙供设备。 3、洛溪水厂： （1）南站水厂预处理区格栅系统甲供，生物反应池和出水及消毒区设备乙供。 二、安装费 1、中部水厂：工艺不同，南站水厂无高效沉淀池和二沉池系统。 2、环城北：结构形式不同，环城北是半地下式，南站水厂是全埋式，涉及地下暗室增加费。 3、洛溪水厂：污水处理规模不同。
A22: 1.1 | B22: 预处理区 | C22: ==197.4 -> 197.4 | D22: ==370.67 -> 370.67 | E22: ==F22*0.1 -> 5.672 | F22: ==56.72 -> 56.72 | G22: ==C22+E22 -> 203.072 | H22: ==D22+F22 -> 427.39 | I22: ==22.38+84.52 -> 106.9 | J22: ==223.33+1214.46-J11 -> 868.13 | K22: ==6699477.07/10000-226.96 -> 442.98771 | L22: ==484.76 -> 484.76 | M22: ==(13066219.29+35471.24-10136098.81*1.09)/10000 -> 205.33428 | N22: ==10136098.81*1.13/10000 -> 1145.3792
A23: 1.2 | B23: 生物反应池 | C23: ==25.84 -> 25.84 | D23: ==620.68 -> 620.68 | E23: ==F23*0.1 -> 2.3482056 | F23: ==234820.56/10000 -> 23.482056 | G23: ==C23+E23 -> 28.188206 | H23: ==D23+F23 -> 644.16206 | I23: 332.21 | J23: ==1104.15-386 -> 718.15 | L23: 284.46 | M23: ==(13732603.83-7372886.14*1.09)/10000 -> 569.61579 | N23: ==7372886.14*1.13/10000 -> 833.13613
A24: 1.3 | B24: MBR膜池 | C24: ==4.49 -> 4.49 | D24: ==141.61 -> 141.61 | E24: ==F24*0.1 -> 0 | F24: ==0 -> 0 | G24: ==C24+E24 -> 4.49 | H24: ==D24+F24 -> 141.61 | I24: 0 | J24: 188.5 | L24: 59.87 | M24: / | N24: /
A25: 1.4 | B25: 出水及消毒区 | C25: ==87.67 -> 87.67 | D25: ==217.5 -> 217.5 | E25: ==F25*0.1 -> 50.84 | F25: ==508.4 -> 508.4 | G25: ==C25+E25 -> 138.51 | H25: ==D25+F25 -> 725.9 | I25: 42.99 | J25: 532.46 | L25: 172.27 | M25: ==(17595506.9+2264997.25-(15500198.22+747758.14)*1.09)/10000 -> 215.02317 | N25: ==(15500198.22+747758.14)*1.13/10000 -> 1836.0191
A26: 1.5 | B26: 浓缩池 | C26: ==19.06 -> 19.06 | D26: ==37.29 -> 37.29 | E26: ==F26*0.1 -> 4.326 | F26: ==43.26 -> 43.26 | G26: ==C26+E26 -> 23.386 | H26: ==D26+F26 -> 80.55 | I26: 58.46 | J26: 119.57 | L26: / | M26: ==(91.74-39.74/1.13)+19.97 -> 76.541858 | N26: ==(11032.74+15421.68+8451.33+316814.16)*1.13/10000 -> 39.74435
A27: 1.6 | B27: 放空泵房 | C27: ==56.58 -> 56.58 | D27: ==26.61 -> 26.61 | E27: ==F27*0.1 -> 0 | F27: 0 | G27: ==C27+E27 -> 56.58 | H27: ==D27+F27 -> 26.61 | I27: 19.26 | J27: ==164.61-114.9 -> 49.71 | L27: 133.75 | M27: ==(1093431.08-531539.82*1.09)/10000 -> 51.405268 | N27: ==531539.82*1.13/10000 -> 60.064
A28: 1.7 | B28: 鼓风机房 | C28: ==88.24 -> 88.24 | D28: ==37.04 -> 37.04 | E28: ==F28*0.1 -> 0 | F28: 0 | G28: ==C28+E28 -> 88.24 | H28: ==D28+F28 -> 37.04 | I28: 85.72 | J28: ==1197.63-1143.22 -> 54.41 | L28: ==21.33 -> 21.33 | M28: ==(908383.68-104558.59*1.09)/10000 -> 79.441482 | N28: ==104558.59*1.13/10000 -> 11.815121
A29: 1.8 | B29: 加药间 | C29: ==47.09 -> 47.09 | D29: ==140.12 -> 140.12 | E29: ==F29*0.1 -> 23.276 | F29: 232.76 | G29: ==C29+E29 -> 70.366 | H29: ==D29+F29 -> 372.88 | I29: 79.48 | J29: 188.87 | L29: 34.85 | M29: ==(66.02-38.4/1.13)+9.98 -> 42.017699 | N29: ==78.14-39.74 -> 38.4
A30: 1.9 | B30: 高效沉淀池 | C30: / | D30: / | E30: / | F30: / | G30: / | H30: / | I30: / | J30: / | L30: 520.03 | M30: ==(1518526.32-248027.5*1.09)/10000 -> 124.81763 | N30: ==248027.5*1.13/10000+1300 -> 1328.0271
A31: 1.1 | B31: 二沉池 | C31: / | D31: / | E31: / | F31: / | G31: / | H31: / | I31: / | J31: / | M31: ==(4688890.04-697272.42*1.09)/10000 -> 392.88631 | N31: ==697272.42*1.13/10000+480 -> 558.79178
A32: 1.11 | B32: 维修车间 | C32: ==1.08 -> 1.08 | D32: ==2.83 -> 2.83 | E32: ==F32*0.1 -> 0 | F32: 0 | G32: ==C32+E32 -> 1.08 | H32: ==D32+F32 -> 2.83 | I32: 0 | J32: ==21.17+92.15 -> 113.32 | L32: 9.86 | M32: ==(104277.5-81035.4*1.09)/10000 -> 1.5948914 | N32: ==81035.4*1.13/10000 -> 9.1570002
A33: 1.12 | B33: 工艺综合管线 | C33: ==272.72 -> 272.72 | D33: ==9.23 -> 9.23 | E33: ==F33*0.1 -> 0 | F33: 0 | G33: ==C33+E33 -> 272.72 | H33: ==D33+F33 -> 9.23 | I33: 687.13 | J33: ==235.04+10 -> 245.04 | K33: 220.36 | L33: 9.41 | M33: ==(1664261.73-53097.35*1.09)/10000 -> 160.63856 | N33: ==53097.35*1.13/10000 -> 6.0000006
A34: 2 | B34: 仪表自控专业 （首期90%、远期10%） | C34: 347.46 | D34: 1105.25 | E34: 38.61 | F34: 122.81 | G34: ==C34+E34 -> 386.07 | H34: ==D34+F34 -> 1228.06 | I34: 1096.83 | J34: ==1226.45-104.8 -> 1121.65 | K34: ==(1392951.6+246173.88)/10000 -> 163.91255 | L34: ==(3506260+2861504)/10000-L18 -> 516.3524 | M34: ==(23696286.07-15301218.04*1.09)/10000 -> 701.79584 | N34: ==15301218.04*1.13/10000-314.68 -> 1414.3576 | O34: 偏差原因： 一、经对比分析，“南站”、“环城北”和“中部”设备配置及价值水平基本一致； 二、基于安装与设备费占比通常为30%~50%： 1.“环城北”安装费异常偏高； 2.“中部”因建面较大，线缆配置需求较“南站”大，故安装费稍高于“南站”，但属合理范围内。
A35: 3 | B35: 电气专业 （首期80%、远期20%） | C35: ==(32700857.94-762028.01-185537.84-(6547631.99-94646.94-79979.29)*1.09)/10000 -> 2480.6716 | D35: ==(6547631.99-17130.97)*1.13/10000 -> 737.94662 | E35: 400 | F35: 184 | G35: ==C35+E35 -> 2880.6716 | H35: ==D35+F35 -> 921.94662 | I35: ==2120.46+903.7+17.5+85.64 -> 3127.3 | J35: ==1444.97+122.76+70 -> 1637.73 | K35: ==(8735870.42+264248.07+379091.27+47274.27+129858.67+2292379.56+114682.16)/10000 -> 1196.3404 | L35: ==8744319/10000 -> 874.4319 | M35: ==(8505692.48+10405978.9+1895043.72+1090440.24-(3945265.32+2060121.53+181867.96+372159.09)*1.09)/10000 -> 1474.7394 | N35: ==(3945265.32+2060121.53+181867.96+372159.09)*1.13/10000 -> 741.21377 | O35: 偏差原因：安装费因工程量差异；设备费偏差主要是数量和单价的差异。 一、环城北：1.安装费:因工程量差异；2.设备费：2.1南站水厂高压柜（含直流屏）14台，平均单价7.2万/台，低压柜69台，平均单价5.8万/台；环城北高压柜（含直流屏）14台，平均单价10.1万/台，低压柜150台，平均单价6.1万/台，相比少600万；2.2南站水厂配电箱140台，平均单价6600元/台；环城北配电箱457台，平均单价3500元/台，相比少70万，总共少670万。 二、中部净水厂：1.安装费:1.1中部水厂有763万外电未在招标预算范围；1.2.南站水厂母线760米，平均单价5500元/米，中部水厂母线130米，平均单价5500元/米，相比多415万。 三、洛溪首期：1.安装费:因工程量差异；2.设备费：2.1南站水厂高压柜（含直流屏）14台，平均单价7.2万/台，低压柜69台，平均单价5.8万/台；洛溪首期高压柜（含直流屏）10台，平均单价10万/台，低压柜73台，平均单价8万/台，相比少170万；2.2南站水厂电梯3部，平均单价28.2万/部，洛溪首期电梯3部，平均单价13.1万/部，相比多40万，总共少130万。
A36: 4 | B36: 暖通、除臭专业 （首期100%） | C36: ==C37+C38 -> 735.02 | D36: ==D37+D38 -> 687 | E36: ==E37+E38 -> 0 | F36: ==F37+F38 -> 300 | G36: ==G37+G38 -> 735.02 | H36: ==H37+H38 -> 987 | I36: ==I37+I38 -> 618.21 | J36: ==J37+J38 -> 770.49 | ... L36: ==L37+L38 -> 395.934 | M36: ==M37 -> 1684.1155 | N36: ==N37 -> 1483.9777 | O36: 一、经对比分析，“南站”和“中部”设备配置不一致。“中部”设备为“碱洗涤+生物除臭复合滤池”、“化学碱洗涤塔”、“土壤除臭滤池”、“全过程除臭生物填料释放罐”等设备，费用约737万； 二、“南站””和“环城北”相比，设备配置基本一致，“环城北”设备费偏低。
A37: 4.1 | B37: 暖通 | C37: 506.48 | D37: 190.31 | E37: 0 | F37: 0 | G37: ==C37+E37 -> 506.48 | H37: ==D37+F37 -> 190.31 | I37: ==372.78+6.56 -> 379.34 | J37: ==212.86+47.61 -> 260.47 | K37: ==(4892831.43+135713.34)/10000 -> 502.85448 | L37: ==906700/10000 -> 90.67 | M37: ==(29785405.02+1370224.79-(12562539.41+570006.55)*1.09)/10000 -> 1684.1155 | N37: ==(12562539.41+570006.55)*1.13/10000 -> 1483.9777
A38: 4.2 | B38: 除臭 | C38: 228.54 | D38: 496.69 | E38: 0 | F38: 300 | G38: ==C38+E38 -> 228.54 | H38: ==D38+F38 -> 796.69 | I38: ==238.87 -> 238.87 | J38: ==510.02 -> 510.02 | L38: ==3052640/10000 -> 305.264
A39: 5 | B39: 给排水 （首期100%） | I39: ==19.55+397.02 -> 416.57 | J39: ==60.41 -> 60.41 | K39: ==(2470845.58+299898.25)/10000 -> 277.07438 | L39: 0 | M39: ==(496306.72+989426.11+2368731.64-(136689.31+130205.18+81038.49)*1.09)/10000 -> 347.52175 | N39: ==(136689.31+130205.18+81038.49)*1.13/10000 -> 39.316427
A40: 6 | B40: 化验室、维修间设备 | I40: 0 | J40: 166.48 | K40: / | L40: ==361700/10000 -> 36.17 | M40: / | N40: 0
...

Sheet 甲供设备
A1: 设备价格表（含税）
A2: 单位工程：甲供设备
A3: 序号 | B3: 设备名称 | C3: 概算规格、型号 | D3: 施工图预算规格、型号 | E3: 单位 | F3: 数量 | G3: 概算 | I3: 南站水厂（5万m³/d） | M3: 环城北（100000m3/d） | O3: 中部水厂（100000m3/d） | Q3: 洛溪水厂(首期) （5万m³/d） | S3: 南站水厂 | U3: 品牌1 | Y3: 品牌2 | AC3: 品牌3 | AG3: 品牌4
I4: 预算数量 | J4: 预算选用价格
G5: 单价(元) | H5: 合价(元) | J5: 建议下浮率 | K5: 单价（元） | L5: 总价（元） | M5: 单价（元） | N5: 总价（元） | O5: 单价（元） | P5: 总价（元） | Q5: 单价（元） | R5: 总价（元） | S5: 询价均值 | T5: 询价最低值 | U5: 公司名称 | V5: 联系人、联系电话 | W5: 单价（元） | X5: 总价（元） | Y5: 公司名称 | Z5: 联系人、联系电话 | AA5: 单价（元） | AB5: 总价（元） | AC5: 公司名称 | AD5: 联系人、联系电话 | AE5: 单价（元） | AF5: 总价（元） | AG5: 公司名称 | AH5: 联系人、联系电话 | AI5: 单价（元） | AJ5: 总价（元）
A6: 一 | B6: 采购子包1:提升泵及配套设备 | L6: ==SUM(L7:L8) -> 1703337.1 | N6: ==SUM(N7:N8) -> 1149012 | P6: ==SUM(P7:P8) -> 2200000 | R6: ==SUM(R7:R8) -> 1365891
A7: 1 | B7: 提升水泵 | C7: 潜污泵，Q=2083m3/h，H=9.5m，N=75kW，带变频控制、导轨及自耦系统 | D7: 潜污泵，Q=2083m3/h，H=9.5m，N=75kW，带变频控制、导轨及自耦系统 | E7: 台 | F7: 2 | G7: 683200 | H7: ==G7*F7 -> 1366400 | I7: 2 | J7: 0.125 | K7: ==ROUND(S7*(1-J7),2) -> 499774.19 | L7: ==ROUND(K7*I7,2) -> 999548.38 | M7: 383004（Q=1300m3/h,H=25m,P=140kW） | N7: ==383004*3 -> 1149012 | O7: 440000（Q=1565m3/h，H=9.0m，N=55kw） | P7: ==440000*5 -> 2200000 | Q7: 322908（Q=1880m3/h ，H=6.0m ，N=55kW） | R7: ==322908*2 -> 645816 | S7: ==AVERAGE(W7,AA7,AE7,AI7) -> 571170.5 | T7: ==MIN(W7,AA7,AE7,AI7) -> 334682 | U7: KSB | V7: 李晖13829709122 | W7: 780000 | X7: ==W7*F7 -> 1560000 | Y7: 飞力 | Z7: 陈工18218182708 | AA7: 490000 | AB7: ==AA7*F7 -> 980000 | AC7: 海斯特 | AD7: 王兰军18666867936 | AE7: 680000 | AF7: ==AE7*F7 -> 1360000 | AG7: ABS | AH7: 曹昀13503012388 | AI7: 334682 | AJ7: ==AI7*I7 -> 669364
A8: 2 | B8: 提升水泵 | C8: 潜污泵，Q=1041m3/h，H=9.5m，N=37kW，带变频控制、导轨及自耦系统 | D8: 潜污泵，Q=1041m3/h，H=9.5m，N=37kW，带变频控制、导轨及自耦系统 | E8: 台 | F8: 2 | G8: 494500 | H8: ==G8*F8 -> 989000 | I8: 2 | J8: 0.125 | K8: ==ROUND(S8*(1-J8),2) -> 351894.38 | L8: ==ROUND(K8*I8,2) -> 703788.76 | Q8: 240025（Q=1460m3/h ，H=6.0m ，N=37kW） | R8: ==240025*3 -> 720075 | S8: ==AVERAGE(W8,AA8,AE8,AI8) -> 402165 | T8: ==MIN(W8,AA8,AE8,AI8) -> 218660 | U8: KSB | V8: 李晖13829709122 | W8: 665000 | X8: ==W8*F8 -> 1330000 | Y8: 飞力 | Z8: 陈工18218182708 | AA8: 390000 | AB8: ==AA8*F8 -> 780000 | AC8: 海斯特 | AD8: 王兰军18666867936 | AE8: 335000 | AF8: ==AE8*F8 -> 670000 | AG8: ABS | AH8: 曹昀13503012388 | AI8: 218660 | AJ8: ==AI8*I8 -> 437320
A9: 二 | B9: 采购子包2:内进流格栅除污机及其配套设备 | L9: ==SUM(L10:L19) -> 4007279.6 | N9: ==SUM(N10:N19) -> 5696600 | P9: ==SUM(P10:P19) -> 5100000 | R9: ==SUM(R10:R19) -> 7184068
A10: 1 | B10: 细格栅 | C10: 内进流孔板式格栅，渠宽1.5m，栅隙5mm，N=0.75kW，单台过水量≥2100m3/h，主体不锈钢 | D10: 内进流孔板式格栅，渠宽1.5m，栅隙5mm，N=0.75kW，单台过水量≥2100m3/h，主体不锈钢 | E10: 台 | F10: 3 | G10: 2377400 | H10: ==G10 -> 2377400 | I10: 3 | J10: 0.365 | K10: ==ROUND(S10*(1-J10),2) -> 601274.44 | L10: ==ROUND(K10*I10,2) -> 1803823.3 | M10: 531160 （Q=1565m3/h，b=5mm） | N10: ==265.58*10000 -> 2655800 | O10: 700000 | P10: ==O10*3 -> 2100000 | Q10: ==2744068/3 -> 914689.33 | R10: ==Q10*3 -> 2744068 | S10: ==AVERAGE(X10,AB10+AB11+AB12+AB13+AB14,AF10+AF11+AF12+AF13+AF14)/3 -> 946888.89 | T10: ==MIN(W10,AA10,AE10,AI10) -> 722433.33 | U10: 北排 | V10: 刘小姐13560026763 | W10: ==2167300/3 -> 722433.33 | X10: ==W10*F10 -> 2167300 | Y10: 悉美 | Z10: 王磷13602392272 | AA10: 890500 | AB10: ==AA10*F10 -> 2671500 | AC10: 艾维 | AD10: 谢泽才18620056917 | AE10: 860000 | AF10: ==AE10*F10 -> 2580000
A11: 2 | B11: 螺旋压榨机 | C11: 过滤精度3mm， N=2.2kW | D11: 过滤精度3mm， N=2.2kW | E11: 台 | F11: 2 | I11: 2 | U11: 北排 | V11: 刘小姐13560026763 | Y11: 悉美 | Z11: 王磷13602392272 | AA11: 182600 | AB11: ==AA11*F11 -> 365200 | AC11: 艾维 | AD11: 谢泽才18620056917 | AE11: 162500 | AF11: ==AE11*F11 -> 325000
A12: 3 | B12: 输渣管 | C12: 与格栅系统配套，长度≈12m，不锈钢材质，含支腿及观察口 | D12: 与格栅系统配套，长度≈12m，不锈钢材质，含支腿及观察口 | E12: 套 | F12: 1 | I12: 1 | U12: 北排 | V12: 刘小姐13560026763 | Y12: 悉美 | Z12: 王磷13602392272 | AA12: 18000 | AB12: ==AA12*F12 -> 18000 | AC12: 艾维 | AD12: 谢泽才18620056917 | AE12: 100000 | AF12: ==AE12*F12 -> 100000
A13: 4 | B13: 冲洗泵组 | C13: 立式多级泵组，单泵Q=8m³/h，H=81m，N=3kW，带变频控制、进口过滤器 | D13: 立式多级泵组，单泵Q=8m³/h，H=81m，N=3kW，带变频控制、进口过滤器 | E13: 台 | F13: 5 | I13: 5 | U13: 北排 | V13: 刘小姐13560026763 | Y13: 悉美 | Z13: 王磷13602392272 | AA13: 15000 | AB13: ==AA13*F13 -> 75000 | AC13: 艾维 | AD13: 谢泽才18620056917 | AE13: 22000 | AF13: ==AE13*F13 -> 110000
A14: 5 | B14: 储水箱 | C14: 不锈钢方形水箱，V=12m3，含成套冲洗水管路控制阀门、接头、过滤器、仪表等 | D14: 不锈钢方形水箱，V=12m3，含成套冲洗水管路控制阀门、接头、过滤器、仪表等 | E14: 个 | F14: 1 | I14: 1 | U14: 北排 | V14: 刘小姐13560026763 | Y14: 悉美 | Z14: 王磷13602392272 | AA14: 10000 | AB14: ==AA14*F14 -> 10000 | AC14: 艾维 | AD14: 谢泽才18620056917 | AE14: 100000 | AF14: ==AE14*F14 -> 100000
A15: 6 | B15: 膜格栅 | C15: 内进流孔板式格栅，渠宽1.6m，栅隙1mm，N=2.2kW ，网板宽度1800mm，单台过水量≥1580m3/h | D15: 内进流孔板式格栅，渠宽1.6m，栅隙1mm，N=2.2kW ，网板宽度1800mm，单台过水量≥1580m3/h | E15: 台 | F15: 3 | G15: 2935300 | H15: ==G15 -> 2935300 | I15: 3 | J15: 0.375 | K15: ==ROUND(S15*(1-J15),2) -> 734485.42 | L15: ==ROUND(K15*F15,2) -> 2203456.3 | M15: 608160（Q=1565m3/h，b=1mm） | N15: ==304.08*10000 -> 3040800 | O15: 750000 | P15: ==O15*4 -> 3000000 | Q15: ==4440000/3 -> 1480000 | R15: ==Q15*3 -> 4440000 | S15: ==AVERAGE(X15,AB15+AB16+AB17+AB18+AB19,AF15+AF16+AF17+AF18+AF19)/3 -> 1175176.7 | T15: ==MIN(W15,AA15,AE15,AI15) -> 884896.67 | U15: 北排 | V15: 刘小姐13560026763 | W15: ==2654690/3 -> 884896.67 | X15: ==W15*F15 -> 2654690 | Y15: 悉美 | Z15: 王磷13602392272 | AA15: 1229500 | AB15: ==AA15*F15 -> 3688500 | AC15: 艾维 | AD15: 谢泽才18620056917 | AE15: 1020000 | AF15: ==AE15*F15 -> 3060000
A16: 7 | B16: 螺旋压榨机 | C16: 过滤精度2mm，N=3kW | D16: 过滤精度2mm，N=3kW | E16: 台 | F16: 2 | I16: 2 | U16: 北排 | V16: 刘小姐13560026763 | Y16: 悉美 | Z16: 王磷13602392272 | AA16: 188700 | AB16: ==AA16*F16 -> 377400 | AC16: 艾维 | AD16: 谢泽才18620056917 | AE16: 163500 | AF16: ==AE16*F16 -> 327000
A17: 8 | B17: 输渣管 | C17: 与格栅系统配套，长度≈16m，不锈钢材质，含支腿及观察口 | D17: 与格栅系统配套，长度≈16m，不锈钢材质，含支腿及观察口 | E17: 套 | F17: 1 | I17: 1 | U17: 北排 | V17: 刘小姐13560026763 | Y17: 悉美 | Z17: 王磷13602392272 | AA17: 21000 | AB17: ==AA17*F17 -> 21000 | AC17: 艾维 | AD17: 谢泽才18620056917 | AE17: 110000 | AF17: ==AE17*F17 -> 110000
A18: 9 | B18: 恒压冲洗泵组 | C18: 立式多级泵组，单泵Q=30m³/h，H=80m，N=11kW，带变频控制、进口过滤器 | D18: 立式多级泵组，单泵Q=30m³/h，H=80m，N=11kW，带变频控制、进口过滤器 | E18: 台 | F18: 3 | I18: 3 | U18: 北排 | V18: 刘小姐13560026763 | Y18: 悉美 | Z18: 王磷13602392272 | AA18: 35000 | AB18: ==AA18*F18 -> 105000 | AC18: 艾维 | AD18: 谢泽才18620056917 | AE18: 40666.67 | AF18: ==AE18*F18 -> 122000.01
A19: 10 | B19: 储水箱 | C19: 不锈钢方形水箱，V=12m3，含成套冲洗水管路控制阀门、接头、过滤器、仪表等 | D19: 不锈钢方形水箱，V=12m3，含成套冲洗水管路控制阀门、接头、过滤器、仪表等 | E19: 个 | F19: 1 | I19: 1 | U19: 北排 | V19: 刘小姐13560026763 | Y19: 悉美 | Z19: 王磷13602392272 | AA19: 10000 | AB19: ==AA19*F19 -> 10000 | AC19: 艾维 | AD19: 谢泽才18620056917 | AE19: 101000 | AF19: ==AE19*F19 -> 101000
A20: 三 | B20: 采购子包3:立式搅拌器及配套设备 | L20: ==SUM(L21:L22) -> 1007787.5 | N20: ==SUM(N21:N22) -> 1650000 | P20: ==SUM(P21:P22) -> 690000 | R20: ==SUM(R21:R22) -> 1248390
A21: 1 | B21: 厌氧搅拌器 | C21: 不锈钢立式搅拌器，D=4m，N=4kW，带变频控制，缺氧Ⅰ | D21: 不锈钢立式搅拌器，D=4m，N=4kW，带变频控制，缺氧Ⅰ | E21: 台 | F21: 4 | G21: 156000 | H21: ==G21*F21 -> 624000 | I21: 5 | J21: 0.26 | K21: ==ROUND(S21*(1-J21),2) -> 94464.7 | L21: ==ROUND(K21*I21,2) -> 472323.5 | M21: 55000（D=580mm；转速475rpm；N=7.6kw） | N21: ==165*10000 -> 1650000 | O21: 115000 | P21: ==O21*2 -> 230000 | Q21: 83226 | R21: ==Q21*10 -> 832260 | S21: ==AVERAGE(W21,AA21,AE21,AI21) -> 127655 | T21: ==MIN(W21,AA21,AE21,AI21) -> 120310 | U21: 菲力 | V21: 史伟15161663888 | W21: 135000 | X21: ==W21*I21 -> 675000 | Y21: 莱宁 | Z21: 王晨18664634927 | AA21: 不报价 | AB21: 不报价 | AC21: 力维 | AD21: 方经理13801994720 | AE21: 120310 | AF21: ==AE21*I21 -> 601550
A22: 2 | B22: 缺氧搅拌器 | C22: 不锈钢立式搅拌器，D=4.2m，N=7.5kW，带变频控制，缺氧Ⅱ | D22: 不锈钢立式搅拌器，D=4.2m，N=7.5kW，带变频控制，缺氧Ⅱ | E22: 套 | F22: 4 | G22: 169000 | H22: ==G22*F22 -> 676000 | I22: 5 | J22: 0.26 | K22: ==ROUND(S22*(1-J22),2) -> 107092.8 | L22: ==ROUND(K22*I22,2) -> 535464 | O22: 115000 | P22: ==O22*4 -> 460000 | Q22: 83226 | R22: ==Q22*5 -> 416130 | S22: ==AVERAGE(W22,AA22,AE22,AI22) -> 144720 | T22: ==MIN(W22,AA22,AE22,AI22) -> 129440 | U22: 菲力 | V22: 史伟15161663888 | W22: 160000 | X22: ==W22*I22 -> 800000 | Y22: 莱宁 | Z22: 王晨18664634927 | AA22: 不报价 | AB22: 不报价 | AC22: 力维 | AD22: 方经理13801994720 | AE22: 129440 | AF22: ==AE22*I22 -> 647200
A23: 四 | B23: 采购子包4:潜水推流器及配套设备 | L23: ==L24 -> 600838 | N23: ==N24 -> 2210000 | P23: ==P24 -> 2160000 | R23: ==R24 -> 334650
A24: 1 | B24: 缺氧推流器 | C24: 不锈钢低速推流器，N=15kW | D24: 不锈钢低速推流器，N=15kW | E24: 台 | F24: 4 | G24: 170000 | H24: ==G24*F24 -> 680000 | I24: 5 | J24: 0.51 | K24: ==ROUND(S24*(1-J24),2) -> 120167.6 | L24: ==ROUND(K24*I24,2) -> 600838 | M24: 85000（D=2500mm;转速48rpm；N=6.8kw） | N24: ==221*10000 -> 2210000 | O24: 135000 | P24: ==O24*16 -> 2160000 | Q24: 111550 | R24: ==Q24*3 -> 334650 | S24: ==AVERAGE(W24,AA24,AE24,AI24) -> 245240 | T24: ==MIN(W24,AA24,AE24,AI24) -> 195000 | U24: KSB | V24: 李晖13829709122 | W24: 195000 | X24: ==W24*I24 -> 975000 | Y24: 飞力 | Z24: 陈工18218182708 | AA24: 225000 | AB24: ==AA24*I24 -> 1125000 | AC24: 海斯特 | AD24: 王兰军18666867936 | AE24: 285000 | AF24: ==AE24*I24 -> 1425000 | AG24: ABS | AH24: 曹昀13503012388 | AI24: 275960 | AJ24: ==AI24*I24 -> 1379800
A25: 五 | B25: 采购子包5:MBR膜池工艺系统及配套设备（50%） | L25: ==L26 -> 33055671 | N25: ==N26 -> 63188094 | P25: ==P26 -> / | R25: ==R26 -> 25984134
A26: 1 | B26: 膜组器系统 | C26: PVDF中空纤维膜组器，单渠道出水量Q≥9375m3/d，组器框架不锈钢材质，含产水、曝气接头等 | D26: PVDF中空纤维膜组器,单渠道出水量Q≥9375m3/d,组器框架不锈钢材质,含产水、曝气接头等,每个渠道含8套膜组器 | E26: 台 | F26: 8 | G26: 32000000 | H26: 32000000 | I26: 1 | J26: 0.02 | K26: ==ROUND(S26*(1-J26),2) -> 33055671 | L26: ==K26*I26 -> 33055671 | M26: 6507.31万元（100000m3/d），其中膜组器2860000.00元（Q=6250m3/d） | N26: ==65073094-1885000 -> 63188094 | O26: / | P26: / | Q26: ==23714533+2269601.11 -> 25984134 | R26: ==Q26 -> 25984134 | S26: 33730276 | T26: ==AA26 -> 29726630 | U26: 碧水源 | V26: 车学理13380060528 | W26: 3152000 | X26: ==W26*F26 -> 25216000 | Y26: 三达膜 | Z26: 王立才13459293295 | AA26: 29726630 | AB26: ==AA26 -> 29726630 | AC26: 立升 | AD26: 房明亮15050461263 | AE26: 不报价 | AF26: 不报价
A27: 2 | B27: 进水闸门 | C27: 不锈钢附壁方闸门，B×H=1000×1000mm，N=0.75kW，带手电一体启闭机 | D27: 不锈钢附壁方闸门，B×H=1000×1000mm，N=0.75kW，带手电一体启闭机 | E27: 台 | F27: 8 | U27: 碧水源 | V27: 车学理13380060528 | W27: 58000 | X27: ==W27*F27 -> 464000 | Y27: 三达膜 | Z27: 王立才13459293295 | AC27: 立升 | AD27: 房明亮15050461263 | AE27: 不报价 | AF27: 不报价
A28: 3 | B28: 出水闸门 | C28: 不锈钢附壁方闸门，B×H=1000×1000mm，N=0.75kW，带手电一体启闭机 | D28: 不锈钢附壁方闸门，B×H=1000×1000mm，N=0.75kW，带手电一体启闭机 | E28: 台 | F28: 8 | U28: 碧水源 | V28: 车学理13380060528 | W28: 58000 | X28: ==W28*F28 -> 464000 | Y28: 三达膜 | Z28: 王立才13459293295 | AC28: 立升 | AD28: 房明亮15050461263 | AE28: 不报价 | AF28: 不报价
A29: 4 | B29: 电动葫芦 | C29: 起重量5T，起吊高度12m，行程约340m，N=0.8×2+7.5kW | D29: 起重量5T，起吊高度12m，行程约340m，N=0.8×2+7.5kW | E29: 台 | F29: 2 | U29: 碧水源 | V29: 车学理13380060528 | W29: 436000 | X29: ==W29*F29 -> 872000 | Y29: 三达膜 | Z29: 王立才13459293295 | AC29: 立升 | AD29: 房明亮15050461263 | AE29: 不报价 | AF29: 不报价
A30: 5 | B30: 产水泵 | C30: 卧式离心泵，Q=481m3/h，H=17m，N=37kW，汽蚀余量≤3m，带变频控制 | D30: 卧式离心泵，Q=481m3/h，H=20m，N=37kW，汽蚀余量≤3m，带变频控制 | E30: 台 | F30: 9 | U30: 碧水源 | V30: 车学理13380060528 | W30: 54620 | X30: ==W30*F30 -> 491580 | Y30: 三达膜 | Z30: 王立才13459293295 | AC30: 立升 | AD30: 房明亮15050461263 | AE30: 不报价 | AF30: 不报价
A31: 6 | B31: 产水专用设备 | C31: Φ500×1100mm，SS316材质，每套含2个音叉液位计 | D31: Φ500×1100mm，SS316材质，每套含2个音叉液位计 | E31: 台 | F31: 8 | U31: 碧水源 | V31: 车学理13380060528 | W31: 17795 | X31: ==W31*F31 -> 142360 | Y31: 三达膜 | Z31: 王立才13459293295 | AC31: 立升 | AD31: 房明亮15050461263 | AE31: 不报价 | AF31: 不报价
A32: 7 | B32: CIP泵 | C32: 卧式离心泵，Q=251m3/h,H=12m,N=15kW，带变频控制 | D32: 卧式离心泵，Q=251m3/h,H=12m,N=15kW，带变频控制 | E32: 台 | F32: 2 | U32: 碧水源 | V32: 车学理13380060528 | W32: 43346 | X32: ==W32*F32 -> 86692 | Y32: 三达膜 | Z32: 王立才13459293295 | AC32: 立升 | AD32: 房明亮15050461263 | AE32: 不报价 | AF32: 不报价
A33: 8 | B33: 液环真空泵 | C33: Q=165m3/h，最大真空度84%，N=4kW | D33: Q=165m3/h，最大真空度84%，N=4kW | E33: 台 | F33: 2 | U33: 碧水源 | V33: 车学理13380060528 | W33: 30000 | X33: ==W33*F33 -> 60000 | Y33: 三达膜 | Z33: 王立才13459293295 | AC33: 立升 | AD33: 房明亮15050461263 | AE33: 不报价 | AF33: 不报价
A34: 9 | B34: 真空罐 | C34: V=1m3，Φ800×2400mm | D34: V=1m3，Φ800×2400mm | E34: 台 | F34: 1 | U34: 碧水源 | V34: 车学理13380060528 | W34: 10000 | X34: ==W34*F34 -> 10000 | Y34: 三达膜 | Z34: 王立才13459293295 | AC34: 立升 | AD34: 房明亮15050461263 | AE34: 不报价 | AF34: 不报价
A35: 10 | B35: 气水分离罐 | C35: V=0.12m3，φ500×780mm | D35: V=0.12m3，φ500×780mm | E35: 台 | F35: 1 | U35: 碧水源 | V35: 车学理13380060528 | W35: 3000 | X35: ==W35*F35 -> 3000 | Y35: 三达膜 | Z35: 王立才13459293295 | AC35: 立升 | AD35: 房明亮15050461263 | AE35: 不报价 | AF35: 不报价
A36: 11 | B36: 空压机 | C36: 螺杆式空压机，Q=1.0m3/min，P=0.80MPa，N=7.5kW | D36: 螺杆式空压机，Q=1.0m3/min，P=0.80MPa，N=7.5kW | E36: 台 | F36: 2 | U36: 碧水源 | V36: 车学理13380060528 | W36: 43000 | X36: ==W36*F36 -> 86000 | Y36: 三达膜 | Z36: 王立才13459293295 | AC36: 立升 | AD36: 房明亮15050461263 | AE36: 不报价 | AF36: 不报价
A37: 12 | B37: 冷干机 | C37: Q=1.5m3/min，N=0.55kW | D37: Q=1.5m3/min，N=0.55kW | E37: 台 | F37: 1 | U37: 碧水源 | V37: 车学理13380060528 | W37: 7000 | X37: ==W37*F37 -> 7000 | Y37: 三达膜 | Z37: 王立才13459293295 | AC37: 立升 | AD37: 房明亮15050461263 | AE37: 不报价 | AF37: 不报价
A38: 13 | B38: 储气罐 | C38: V=1m3，工作压力0.8MPa | D38: V=1m3，工作压力0.8MPa | E38: 台 | F38: 1 | U38: 碧水源 | V38: 车学理13380060528 | W38: 10000 | X38: ==W38*F38 -> 10000 | Y38: 三达膜 | Z38: 王立才13459293295 | AC38: 立升 | AD38: 房明亮15050461263 | AE38: 不报价 | AF38: 不报价
A39: 14 | B39: 剩余污泥泵 | C39: 无堵塞卧式离心泵，Q=65m3/h，H=20m，N=11kW | D39: 无堵塞卧式离心泵，Q=65m3/h，H=20m，N=11kW | E39: 台 | F39: 2 | U39: 碧水源 | V39: 车学理13380060528 | W39: 58000 | X39: ==W39*F39 -> 116000 | Y39: 三达膜 | Z39: 王立才13459293295 | AC39: 立升 | AD39: 房明亮15050461263 | AE39: 不报价 | AF39: 不报价
A40: 17 | B40: 手动对夹式蝶阀 | D40: DN300,1.0MPa,阀板:铸铁 | E40: 个 | F40: 16 | U40: 碧水源 | V40: 车学理13380060528 | W40: 2682 | X40: ==W40*F40 -> 42912 | Y40: 三达膜 | Z40: 王立才13459293295 | AC40: 立升 | AD40: 房明亮15050461263 | AE40: 不报价 | AF40: 不报价
...

Sheet 工艺专业
A1: 设备价格表（含税）
A2: 单位工程：工艺专业
A3: 序号 | B3: 设备名称 | C3: 概算规格、型号 | D3: 施工图预算规格、型号 | E3: 单位 | F3: 数量 | G3: 概算 | I3: 南站水厂 | O3: 环城北 | P3: 中部净水厂 | Q3: 洛溪水厂 | R3: 询价均值 | S3: 询价最低值 | T3: 品牌1 | Z3: 品牌2 | AF3: 品牌3 | AL3: 品牌4
I4: 预算数量 | J4: 预算选用价格 | M4: 招控价选用价格
G5: 单价(元) | H5: 合价(元) | J5: 建议下浮率 | K5: 单价（元） | L5: 总价（元） | M5: 单价 | N5: 差额 | O5: 单价（元） | P5: 单价（元） | Q5: 单价（元） | T5: 公司名称 | U5: 联系人、联系电话 | V5: 单价（元） | W5: 下浮率 | X5: 下浮后单价（元） | Y5: 总价（元） | Z5: 公司名称 | AA5: 联系人、联系电话 | AB5: 单价（元） | AC5: 下浮率 | AD5: 下浮后单价（元） | AE5: 总价（元） | AF5: 公司名称 | AG5: 联系人、联系电话 | AH5: 单价（元） | AI5: 下浮率 | AJ5: 下浮后单价（元） | AK5: 总价（元） | AL5: 公司名称 | AM5: 联系人、联系电话 | AN5: 单价（元） | AO5: 下浮率 | AP5: 下浮后单价（元） | AQ5: 总价（元）
A6: 一 | B6: 进水闸门井、粗格栅及进水泵房
A7: 1 | B7: 进水速闭闸门 | D7: 断电速闭, 1400x1400mm , N=3kW ,配套一体式执行机构 | E7: 台 | F7: 1 | G7: ==416700 -> 416700 | H7: ==G7*F7 -> 416700 | I7: 1 | J7: ==AC7 -> 0.2 | K7: ==S7 -> 119200 | L7: ==F7*K7 -> 119200 | O7: 400000 | P7: 185000 (∅1200,P=1.5kW) | Q7: 780000 (DN1600 ，PN= 1.0MPa ，N=3kW) | R7: ==AVERAGE(X7,AD7,AJ7,AP7) -> 299200 | S7: ==MIN(X7,AD7,AJ7,AP7) -> 119200 | T7: 新环环保 | U7: 连皓文13500036502 | V7: 490000 | W7: 0.2 | X7: ==V7*(1-W7) -> 392000 | Y7: ==X7*I7 -> 392000 | Z7: 无锡通用 | AA7: 杨培根18961775586 | AB7: 149000 | AC7: 0.2 | AD7: ==AB7*(1-AC7) -> 119200 | AE7: ==AB7*I7 -> 149000 | AF7: 江苏南通 | AG7: 李向阳 15896274137 | AH7: 386400 | AJ7: ==AH7*(1-AI7) -> 386400 | AK7: ==AH7*I7 -> 386400
A8: 3 | B8: 格栅进水闸门 | D8: 不锈钢附壁方闸门, 1500 × 1500mm , N=2.2kW ,带手电一体启闭机 | E8: 台 | F8: 3 | G8: 123800 | H8: ==G8*F8 -> 371400 | I8: 3 | J8: ==AC8 -> 0.2 | K8: ==S8 -> 47920 | L8: ==F8*K8 -> 143760 | O8: 60375（B×H=1.50×1.35m，渠深2m，N=1.5kW） | P8: 123667（BxH=2.1X2.9m,P=2.2kw） | Q8: 68650(B*H= 1200*1200m N=0.45kw) | R8: ==AVERAGE(X8,AD8,AJ8,AP8) -> 74760 | S8: ==MIN(X8,AD8,AJ8,AP8) -> 47920 | T8: 新环环保 | U8: 连皓文13500036502 | V8: 118000 | W8: 0.2 | X8: ==V8*(1-W8) -> 94400 | Y8: ==X8*I8 -> 283200 | Z8: 无锡通用 | AA8: 杨培根18961775586 | AB8: 59900 | AC8: 0.2 | AD8: ==AB8*(1-AC8) -> 47920 | AE8: ==AB8*I8 -> 179700 | AF8: 江苏南通 | AG8: 李向阳 15896274137 | AH8: 81960 | AJ8: ==AH8*(1-AI8) -> 81960 | AK8: ==AH8*I8 -> 245880
A9: 4 | B9: 粗格栅 | D9: 钢丝绳牵引式格栅除污机,渠宽 1700mm ,栅隙 15mm , N=1.5+0.55kW ,单台过水量≥ 3300m3/h ,带防臭罩 | E9: 台 | F9: 2 | G9: 241700 | H9: ==G9*F9 -> 483400 | I9: 2 | J9: ==AC9 -> 0.2 | K9: ==S9 -> 228000 | L9: ==F9*K9 -> 456000 | Q9: 180000 | R9: ==AVERAGE(X9,AD9,AJ9,AP9) -> 356533.33 | S9: ==MIN(X9,AD9,AJ9,AP9) -> 228000 | T9: 新环环保 | U9: 连皓文13500036502 | V9: 650000 | W9: 0.2 | X9: ==V9*(1-W9) -> 520000 | Y9: ==X9*I9 -> 1040000 | Z9: 无锡通用 | AA9: 杨培根18961775586 | AB9: 285000 | AC9: 0.2 | AD9: ==AB9*(1-AC9) -> 228000 | AE9: ==AB9*I9 -> 570000 | AF9: 江苏南通 | AG9: 李向阳 15896274137 | AH9: 321600 | AJ9: ==AH9*(1-AI9) -> 321600 | AK9: ==AH9*I9 -> 643200
A10: 5 | B10: 格栅出水闸门 | D10: 不锈钢附壁方闸门, 1500 × 1500mm , N=2.2kW ,带手电一体启闭机 | E10: 台 | F10: 3 | G10: 123900 | H10: ==G10*F10 -> 371700 | I10: 3 | J10: ==AC10 -> 0.2 | K10: ==S10 -> 47920 | L10: ==F10*K10 -> 143760 | O10: 60375（B×H=1.50×1.35m，渠深2m，N=1.5kW） | P10: 123667（BxH=2.1X2.9m,P=2.2kw） | Q10: 107265 | R10: ==AVERAGE(X10,AD10,AJ10,AP10) -> 74760 | S10: ==MIN(X10,AD10,AJ10,AP10) -> 47920 | T10: 新环环保 | U10: 连皓文13500036502 | V10: 118000 | W10: 0.2 | X10: ==V10*(1-W10) -> 94400 | Y10: ==X10*I10 -> 283200 | Z10: 无锡通用 | AA10: 杨培根18961775586 | AB10: 59900 | AC10: 0.2 | AD10: ==AB10*(1-AC10) -> 47920 | AE10: ==AB10*I10 -> 179700 | AF10: 江苏南通 | AG10: 李向阳 15896274137 | AH10: 81960 | AJ10: ==AH10*(1-AI10) -> 81960 | AK10: ==AH10*I10 -> 245880
A11: 6 | B11: 泵房进水闸门 | D11: 不锈钢附壁方闸门, 1500 × 1500mm , N=2.2kW ,带手电一体启闭机 | E11: 台 | F11: 3 | G11: 124000 | H11: ==G11*F11 -> 372000 | I11: 3 | J11: ==AC11 -> 0.2 | K11: ==S11 -> 47920 | L11: ==F11*K11 -> 143760 | O11: 60375（B×H=1.50×1.35m，渠深2m，N=1.5kW） | P11: 123667（BxH=2.1X2.9m,P=2.2kw） | Q11: 107265 | R11: ==AVERAGE(X11,AD11,AJ11,AP11) -> 74760 | S11: ==MIN(X11,AD11,AJ11,AP11) -> 47920 | T11: 新环环保 | U11: 连皓文13500036502 | V11: 118000 | W11: 0.2 | X11: ==V11*(1-W11) -> 94400 | Y11: ==X11*I11 -> 283200 | Z11: 无锡通用 | AA11: 杨培根18961775586 | AB11: 59900 | AC11: 0.2 | AD11: ==AB11*(1-AC11) -> 47920 | AE11: ==AB11*I11 -> 179700 | AF11: 江苏南通 | AG11: 李向阳 15896274137 | AH11: 81960 | AJ11: ==AH11*(1-AI11) -> 81960 | AK11: ==AH11*I11 -> 245880
A12: 7 | B12: 螺旋输送机 | D12: 不锈钢无轴螺旋,Φ 300mm ,有效长度 L ≥ 10.0m N=2.2kW ,带密闭盖 | E12: 台 | F12: 1 | G12: 50400 | H12: ==G12*F12 -> 50400 | I12: 1 | J12: ==W12 -> 0.2 | K12: ==S12 -> 54400 | L12: ==F12*K12 -> 54400 | O12: 37900（DN300（U型断面）） | Q12: 104000 （400mm） | R12: ==AVERAGE(X12,AD12,AJ12,AP12) -> 88000 | S12: ==MIN(X12,AD12,AJ12,AP12) -> 54400 | T12: 新环环保 | U12: 连皓文13500036502 | V12: 68000 | W12: 0.2 | X12: ==V12*(1-W12) -> 54400 | Y12: ==X12*I12 -> 54400 | Z12: 无锡通用 | AA12: 杨培根18961775586 | AB12: 115000 | AC12: 0.2 | AD12: ==AB12*(1-AC12) -> 92000 | AE12: ==AB12*I12 -> 115000 | AF12: 江苏南通 | AG12: 李向阳 15896274137 | AH12: 117600 | AJ12: ==AH12*(1-AI12) -> 117600 | AK12: ==AH12*I12 -> 117600
A13: 8 | B13: 螺旋输送机 | D13: 不锈钢无轴螺旋,Φ 300mm ,有效长度 L ≥ 10.0m N=2.2kW ,带密闭盖 | E13: 台 | F13: 1 | G13: 66300 | H13: ==G13*F13 -> 66300 | I13: 1 | J13: ==W13 -> 0.2 | K13: ==S13 -> 54400 | L13: ==F13*K13 -> 54400 | O13: 37900（DN300（U型断面）） | Q13: 104000 （400mm） | R13: ==AVERAGE(X13,AD13,AJ13,AP13) -> 88000 | S13: ==MIN(X13,AD13,AJ13,AP13) -> 54400 | T13: 新环环保 | U13: 连皓文13500036502 | V13: 68000 | W13: 0.2 | X13: ==V13*(1-W13) -> 54400 | Y13: ==X13*I13 -> 54400 | Z13: 无锡通用 | AA13: 杨培根18961775586 | AB13: 115000 | AC13: 0.2 | AD13: ==AB13*(1-AC13) -> 92000 | AE13: ==AB13*I13 -> 115000 | AF13: 江苏南通 | AG13: 李向阳 15896274137 | AH13: 117600 | AJ13: ==AH13*(1-AI13) -> 117600 | AK13: ==AH13*I13 -> 117600
A14: 9 | B14: 垃圾斗车 | D14: 容积 1 立方米,与螺旋输送机配套 | E14: 个 | F14: 1 | G14: 5200 | H14: ==G14*F14 -> 5200 | I14: 1 | J14: ==AC14 -> 0.2 | K14: ==S14 -> 5200 | L14: ==F14*K14 -> 5200 | O14: 6000 | Q14: 5000 | R14: ==AVERAGE(X14,AD14,AJ14,AP14) -> 6466.6667 | S14: ==MIN(X14,AD14,AJ14,AP14) -> 5200 | T14: 新环环保 | U14: 连皓文13500036502 | V14: 8000 | W14: 0.2 | X14: ==V14*(1-W14) -> 6400 | Y14: ==X14*I14 -> 6400 | Z14: 无锡通用 | AA14: 杨培根18961775586 | AB14: 6500 | AC14: 0.2 | AD14: ==AB14*(1-AC14) -> 5200 | AE14: ==AB14*I14 -> 6500 | AF14: 江苏南通 | AG14: 李向阳 15896274137 | AH14: 7800 | AJ14: ==AH14*(1-AI14) -> 7800 | AK14: ==AH14*I14 -> 7800
A15: 10 | B15: 电动葫芦 | D15: 起重量 3T ,起吊高度 18m ,行程 26m , N=4.9kW | E15: 台 | F15: 1 | G15: 33600 | H15: ==G15*F15 -> 33600 | I15: 1 | J15: ==AI15 -> 0 | K15: ==S15 -> 14500 | L15: ==F15*K15 -> 14500 | O15: 65000（起吊重量3T，4.5+0.4kw） | P15: 30000 | Q15: 81054（12m） | R15: ==AVERAGE(X15,AD15,AJ15,AP15) -> 48000 | S15: ==MIN(X15,AD15,AJ15,AP15) -> 14500 | T15: 广州起重机械 | U15: 谢启康13430264951 | V15: 105000 | W15: 0.1 | X15: ==V15*(1-W15) -> 94500 | Y15: ==X15*I15 -> 94500 | Z15: 广州泰克力 | AA15: 陈经理13570054553 | AB15: 35000 | AD15: ==AB15*(1-AC15) -> 35000 | AE15: ==AB15*I15 -> 35000 | AF15: 广东永通 | AG15: 陈经理13924880284 | AH15: 14500 | AJ15: ==AH15*(1-AI15) -> 14500 | AK15: ==AH15*I15 -> 14500
A16: 11 | B16: 进水电动偏心半球 阀 | D16: DN1400 , PN10 , N=4kW | E16: 台 | F16: 1 | G16: 884500 | H16: ==G16*F16 -> 884500 | I16: 1 | J16: ==AC16 -> 0 | K16: ==S16 -> 847055 | L16: ==F16*K16 -> 847055 | M16: ==K16*0.85 -> 719996.75 | N16: ==M16*I16-I16*K16 -> -127058.25 | O16: 459000（液压偏心半球阀DN1200） | Q16: 860000 （DN1600） | R16: ==AVERAGE(X16,AD16,AJ16,AP16) -> 1013076.5 | S16: ==MIN(X16,AD16,AJ16,AP16) -> 847055 | T16: 冠龙 | U16: 黄经理13925121566 | V16: 1813997 | W16: 0.35 | X16: ==V16*(1-W16) -> 1179098.1 | Y16: ==X16*I16 -> 1179098.1 | Z16: 德国VAG | AA16: 吴居并13922353009 | AB16: 847055 | AD16: ==AB16*(1-AC16) -> 847055 | AE16: ==AB16*I16 -> 847055 | AF16: 丹麦AVK | AG16: 蔡文亮13570037656 | AH16: 不生产 | AJ16: 不生产 | AK16: 不生产
A17: 12 | B17: 止回阀 | D17: DN700 , PN10 | E17: 个 | F17: 2 | G17: 162500 | H17: ==G17*F17 -> 325000 | I17: 2 | J17: ==AI17 -> 0 | K17: ==S17 -> 53234 | L17: ==F17*K17 -> 106468 | O17: 8000（DN600） | Q17: 51186 | R17: ==AVERAGE(X17,AD17,AJ17,AP17) -> 83412.333 | S17: ==MIN(X17,AD17,AJ17,AP17) -> 53234 | T17: 冠龙 | U17: 黄经理13925121566 | V17: 158200 | W17: 0.35 | X17: ==V17*(1-W17) -> 102830 | Y17: ==X17*I17 -> 205660 | Z17: 德国VAG | AA17: 吴居并13922353009 | AB17: 94173 | AD17: ==AB17*(1-AC17) -> 94173 | AE17: ==AB17*I17 -> 188346 | AF17: 丹麦AVK | AG17: 蔡文亮13570037656 | AH17: 53234 | AJ17: ==AH17*(1-AI17) -> 53234 | AK17: ==AH17*I17 -> 106468
A18: 13 | B18: 橡胶接头 | D18: DN700 , PN10 | E18: 个 | F18: 2 | G18: 3200 | H18: ==G18*F18 -> 6400 | I18: 2 | J18: ==AI18 -> 0 | K18: ==S18 -> 6515 | L18: ==F18*K18 -> 13030 | O18: 8039（DN600） | Q18: 4830 | R18: ==AVERAGE(X18,AD18,AJ18,AP18) -> 11286.033 | S18: ==MIN(X18,AD18,AJ18,AP18) -> 6515 | T18: 冠龙 | U18: 黄经理13925121566 | V18: 14534 | W18: 0.35 | X18: ==V18*(1-W18) -> 9447.1 | Y18: ==X18*I18 -> 18894.2 | Z18: 德国VAG | AA18: 吴居并13922353009 | AB18: 17896 | AD18: ==AB18*(1-AC18) -> 17896 | AE18: ==AB18*I18 -> 35792 | AF18: 丹麦AVK | AG18: 蔡文亮13570037656 | AH18: 6515 | AJ18: ==AH18*(1-AI18) -> 6515 | AK18: ==AH18*I18 -> 13030
A19: 14 | B19: 电动蝶阀 | D19: DN700 , PN10 ,开关型 | E19: 个 | F19: 2 | G19: 87200 | H19: ==G19*F19 -> 174400 | I19: 2 | J19: ==W19 -> 0.35 | K19: ==S19 -> 61006.4 | L19: ==F19*K19 -> 122012.8 | O19: 108822 （DN1400） | Q19: 97886 (DN900) | R19: ==AVERAGE(X19,AD19,AJ19,AP19) -> 76832.133 | S19: ==MIN(X19,AD19,AJ19,AP19) -> 61006.4 | T19: 冠龙 | U19: 黄经理13925121566 | V19: 93856 | W19: 0.35 | X19: ==V19*(1-W19) -> 61006.4 | Y19: ==X19*I19 -> 122012.8 | Z19: 德国VAG | AA19: 吴居并13922353009 | AB19: 99108 | AD19: ==AB19*(1-AC19) -> 99108 | AE19: ==AB19*I19 -> 198216 | AF19: 丹麦AVK | AG19: 蔡文亮13570037656 | AH19: 70382 | AJ19: ==AH19*(1-AI19) -> 70382 | AK19: ==AH19*I19 -> 140764
A20: 15 | B20: 橡胶接头 | D20: DN1400 , PN10 | E20: 个 | F20: 1 | G20: 14200 | H20: ==G20*F20 -> 14200 | I20: 1 | J20: ==AI20 -> 0 | K20: ==S20 -> 17482 | L20: ==F20*K20 -> 17482 | O20: 46434 | Q20: 5750 （DN800） | R20: ==AVERAGE(X20,AD20,AJ20,AP20) -> 38090.95 | S20: ==MIN(X20,AD20,AJ20,AP20) -> 17482 | T20: 冠龙 | U20: 黄经理13925121566 | V20: 55449 | W20: 0.35 | X20: ==V20*(1-W20) -> 36041.85 | Y20: ==X20*I20 -> 36041.85 | Z20: 德国VAG | AA20: 吴居并13922353009 | AB20: 60749 | AD20: ==AB20*(1-AC20) -> 60749 | AE20: ==AB20*I20 -> 60749 | AF20: 丹麦AVK | AG20: 蔡文亮13570037656 | AH20: 17482 | AJ20: ==AH20*(1-AI20) -> 17482 | AK20: ==AH20*I20 -> 17482
A21: 16 | B21: 电动蝶阀 | D21: DN500 , PN10 ,开关型 | E21: 个 | F21: 2 | G21: 72700 | H21: ==G21*F21 -> 145400 | I21: 2 | J21: ==AI21 -> 0 | K21: ==S21 -> 40808 | L21: ==F21*K21 -> 81616 | O21: 35897（DN600） | Q21: 35149 （DN200） | R21: ==AVERAGE(X21,AD21,AJ21,AP21) -> 57820.117 | S21: ==MIN(X21,AD21,AJ21,AP21) -> 40808 | T21: 冠龙 | U21: 黄经理13925121566 | V21: 77219 | W21: 0.35 | X21: ==V21*(1-W21) -> 50192.35 | Y21: ==X21*I21 -> 100384.7 | Z21: 德国VAG | AA21: 吴居并13922353009 | AB21: 82460 | AD21: ==AB21*(1-AC21) -> 82460 | AE21: ==AB21*I21 -> 164920 | AF21: 丹麦AVK | AG21: 蔡文亮13570037656 | AH21: 40808 | AJ21: ==AH21*(1-AI21) -> 40808 | AK21: ==AH21*I21 -> 81616
A22: 17 | B22: 蝶阀 | D22: DN1200 , PN10 | E22: 个 | F22: 1 | G22: 74100 | H22: ==G22*F22 -> 74100 | I22: 1 | J22: ==W22 -> 0.35 | K22: ==S22 -> 61425 | L22: ==F22*K22 -> 61425 | O22: 93812(电动 ) | Q22: 114800(电动调节法兰式蝶阀) | R22: ==AVERAGE(X22,AD22,AJ22,AP22) -> 92438 | S22: ==MIN(X22,AD22,AJ22,AP22) -> 61425 | T22: 冠龙 | U22: 黄经理13925121566 | V22: 94500 | W22: 0.35 | X22: ==V22*(1-W22) -> 61425 | Y22: ==X22*I22 -> 61425 | Z22: 德国VAG | AA22: 吴居并13922353009 | AB22: 130451 | AD22: ==AB22*(1-AC22) -> 130451 | AE22: ==AB22*I22 -> 130451 | AF22: 丹麦AVK | AG22: 蔡文亮13570037656 | AH22: 85438 | AJ22: ==AH22*(1-AI22) -> 85438 | AK22: ==AH22*I22 -> 85438
A23: 18 | B23: 止回阀 | D23: DN500，PN10 | E23: 个 | F23: 2 | G23: 3837.6 | H23: ==G23*F23 -> 7675.2 | I23: 2 | J23: ==AI23 -> 0 | K23: ==S23 -> 43851 | L23: ==F23*K23 -> 87702 | O23: 8000（DN600） | Q23: 38512 （DN600） | R23: ==AVERAGE(X23,AD23,AJ23,AP23) -> 50769 | S23: ==MIN(X23,AD23,AJ23,AP23) -> 43851 | T23: 冠龙 | U23: 黄经理13925121566 | V23: 69300 | W23: 0.35 | X23: ==V23*(1-W23) -> 45045 | Y23: ==X23*I23 -> 90090 | Z23: 德国VAG | AA23: 吴居并13922353009 | AB23: 63411 | AD23: ==AB23*(1-AC23) -> 63411 | AE23: ==AB23*I23 -> 126822 | AF23: 丹麦AVK | AG23: 蔡文亮13570037656 | AH23: 43851 | AJ23: ==AH23*(1-AI23) -> 43851 | AK23: ==AH23*I23 -> 87702
A24: 19 | B24: 手动蝶阀 | D24: DN100，PN10 | E24: 个 | F24: 4 | G24: 288.725 | H24: ==G24*F24 -> 1154.9 | I24: 4 | J24: ==AI24 -> 0 | K24: ==S24 -> 515 | L24: ==F24*K24 -> 2060 | Q24: / | R24: ==AVERAGE(X24,AD24,AJ24,AP24) -> 4024.5 | S24: ==MIN(X24,AD24,AJ24,AP24) -> 515 | T24: 冠龙 | U24: 黄经理13925121566 | V24: 2030 | W24: 0.35 | X24: ==V24*(1-W24) -> 1319.5 | Y24: ==X24*I24 -> 5278 | Z24: 德国VAG | AA24: 吴居并13922353009 | AB24: 10239 | AD24: ==AB24*(1-AC24) -> 10239 | AE24: ==AB24*I24 -> 40956 | AF24: 丹麦AVK | AG24: 蔡文亮13570037656 | AH24: 515 | AJ24: ==AH24*(1-AI24) -> 515 | AK24: ==AH24*I24 -> 2060
A25: 20 | B25: 手动蝶阀 | D25: DN150，PN10 | E25: 个 | F25: ==6+5 -> 11 | G25: 465.253 | H25: ==G25*F25 -> 5117.783 | I25: ==6+5 -> 11 | J25: ==AI25 -> 0 | K25: ==S25 -> 904 | L25: ==F25*K25 -> 9944 | Q25: 1863 | R25: ==AVERAGE(X25,AD25,AJ25,AP25) -> 4568.1667 | S25: ==MIN(X25,AD25,AJ25,AP25) -> 904 | T25: 冠龙 | U25: 黄经理13925121566 | V25: 3010 | W25: 0.35 | X25: ==V25*(1-W25) -> 1956.5 | Y25: ==X25*I25 -> 21521.5 | Z25: 德国VAG | AA25: 吴居并13922353009 | AB25: 10844 | AD25: ==AB25*(1-AC25) -> 10844 | AE25: ==AB25*I25 -> 119284 | AF25: 丹麦AVK | AG25: 蔡文亮13570037656 | AH25: 904 | AJ25: ==AH25*(1-AI25) -> 904 | AK25: ==AH25*I25 -> 9944
A26: 21 | B26: 止回阀 | D26: DN100，PN10 | E26: 个 | F26: 4 | H26: ==G26*F26 -> 0 | I26: 4 | J26: ==W26 -> 0.35 | K26: ==S26 -> 1619.8 | L26: ==F26*K26 -> 6479.2 | Q26: 4485 （DN200） | R26: ==AVERAGE(X26,AD26,AJ26,AP26) -> 2514.6 | S26: ==MIN(X26,AD26,AJ26,AP26) -> 1619.8 | T26: 冠龙 | U26: 黄经理13925121566 | V26: 2492 | W26: 0.35 | X26: ==V26*(1-W26) -> 1619.8 | Y26: ==X26*I26 -> 6479.2 | Z26: 德国VAG | AA26: 吴居并13922353009 | AB26: 4125 | AD26: ==AB26*(1-AC26) -> 4125 | AE26: ==AB26*I26 -> 16500 | AF26: 丹麦AVK | AG26: 蔡文亮13570037656 | AH26: 1799 | AJ26: ==AH26*(1-AI26) -> 1799 | AK26: ==AH26*I26 -> 7196
A27: 22 | B27: 止回阀 | D27: DN150，PN10 | E27: 个 | F27: 3 | G27: 2408 | H27: ==G27*F27 -> 7224 | I27: 3 | J27: ==AI27 -> 0 | K27: ==S27 -> 3047 | L27: ==F27*K27 -> 9141 | Q27: 3022.5 | R27: ==AVERAGE(X27,AD27,AJ27,AP27) -> 3731.6333 | S27: ==MIN(X27,AD27,AJ27,AP27) -> 3047 | T27: 冠龙 | U27: 黄经理13925121566 | V27: 4746 | W27: 0.35 | X27: ==V27*(1-W27) -> 3084.9 | Y27: ==X27*I27 -> 9254.7 | Z27: 德国VAG | AA27: 吴居并13922353009 | AB27: 5063 | AD27: ==AB27*(1-AC27) -> 5063 | AE27: ==AB27*I27 -> 15189 | AF27: 丹麦AVK | AG27: 蔡文亮13570037656 | AH27: 3047 | AJ27: ==AH27*(1-AI27) -> 3047 | AK27: ==AH27*I27 -> 9141
A28: 23 | B28: 球阀 | D28: DN32 | E28: 个 | F28: 5 | G28: 16.499 | H28: ==G28*F28 -> 82.495 | I28: 5 | J28: ==AI28 -> 0 | K28: ==S28 -> 215 | L28: ==F28*K28 -> 1075 | Q28: 40（DN25） | R28: ==AVERAGE(X28,AD28,AJ28,AP28) -> 1518 | S28: ==MIN(X28,AD28,AJ28,AP28) -> 215 | T28: 冠龙 | U28: 黄经理13925121566 | V28: 1280 | W28: 0.35 | X28: ==V28*(1-W28) -> 832 | Y28: ==X28*I28 -> 4160 | Z28: 德国VAG | AA28: 吴居并13922353009 | AB28: 3507 | AD28: ==AB28*(1-AC28) -> 3507 | AE28: ==AB28*I28 -> 17535 | AF28: 丹麦AVK | AG28: 蔡文亮13570037656 | AH28: 215 | AJ28: ==AH28*(1-AI28) -> 215 | AK28: ==AH28*I28 -> 1075
A29: 24 | B29: 手动蝶阀 | D29: DN200，PN10 | E29: 个 | F29: 2 | G29: 2437.948 | H29: ==G29*F29 -> 4875.896 | I29: 2 | J29: ==AI29 -> 0 | K29: ==S29 -> 1458 | L29: ==F29*K29 -> 2916 | Q29: 1863 （DN150） | R29: ==AVERAGE(X29,AD29,AJ29,AP29) -> 5211.3 | S29: ==MIN(X29,AD29,AJ29,AP29) -> 1458 | T29: 冠龙 | U29: 黄经理13925121566 | V29: 4326 | W29: 0.35 | X29: ==V29*(1-W29) -> 2811.9 | Y29: ==X29*I29 -> 5623.8 | Z29: 德国VAG | AA29: 吴居并13922353009 | AB29: 11364 | AD29: ==AB29*(1-AC29) -> 11364 | AE29: ==AB29*I29 -> 22728 | AF29: 丹麦AVK | AG29: 蔡文亮13570037656 | AH29: 1458 | AJ29: ==AH29*(1-AI29) -> 1458 | AK29: ==AH29*I29 -> 2916
A30: 25 | B30: 止回阀 | D30: DN50，PN10 | E30: 个 | F30: 2 | G30: 138.4 | H30: ==G30*F30 -> 276.8 | I30: 2 | J30: ==W30 -> 0.35 | K30: ==S30 -> 800.8 | L30: ==F30*K30 -> 1601.6 | Q30: / | R30: ==AVERAGE(X30,AD30,AJ30,AP30) -> 1767.9333 | S30: ==MIN(X30,AD30,AJ30,AP30) -> 800.8 | T30: 冠龙 | U30: 黄经理13925121566 | V30: 1232 | W30: 0.35 | X30: ==V30*(1-W30) -> 800.8 | Y30: ==X30*I30 -> 1601.6 | Z30: 德国VAG | AA30: 吴居并13922353009 | AB30: 3260 | AD30: ==AB30*(1-AC30) -> 3260 | AE30: ==AB30*I30 -> 6520 | AF30: 丹麦AVK | AG30: 蔡文亮13570037656 | AH30: 1243 | AJ30: ==AH30*(1-AI30) -> 1243 | AK30: ==AH30*I30 -> 2486
A31: 26 | B31: 手动蝶阀 | D31: DN50，PN10 | E31: 个 | F31: 2 | G31: 210.004 | H31: ==G31*F31 -> 420.008 | I31: 2 | J31: ==AI31 -> 0 | K31: ==S31 -> 298 | L31: ==F31*K31 -> 596 | Q31: / | R31: ==AVERAGE(X31,AD31,AJ31,AP31) -> 3561.6667 | S31: ==MIN(X31,AD31,AJ31,AP31) -> 298 | T31: 冠龙 | U31: 黄经理13925121566 | V31: 1260 | W31: 0.35 | X31: ==V31*(1-W31) -> 819 | Y31: ==X31*I31 -> 1638 | Z31: 德国VAG | AA31: 吴居并13922353009 | AB31: 9568 | AD31: ==AB31*(1-AC31) -> 9568 | AE31: ==AB31*I31 -> 19136 | AF31: 丹麦AVK | AG31: 蔡文亮13570037656 | AH31: 298 | AJ31: ==AH31*(1-AI31) -> 298 | AK31: ==AH31*I31 -> 596
A32: 27 | B32: 闸阀 | D32: DN50，PN10 | E32: 个 | F32: 4 | H32: ==G32*F32 -> 0 | I32: 4 | J32: 0 | K32: 300 | L32: ==F32*K32 -> 1200 | Q32: / | R32: ==AVERAGE(X32,AD32,AJ32,AP32) -> 100 | S32: ==MIN(X32,AD32,AJ32,AP32) -> 0 | AD32: ==AB32*(1-AC32) -> 0 | AJ32: ==AH32*(1-AI32) -> 0 | AO32: 参考大龙 | AP32: 300
A33: 二 | B33: 细格栅渠
A34: 1 | B34: 格栅进出水闸门 | D34: 不锈钢门式插板闸,渠宽 1.5m ,渠深 2.5m ,水深 1.3m , N=2.2kW | E34: 台 | F34: 8 | G34: 88300 | H34: ==G34*F34 -> 706400 | I34: 8 | J34: ==AC34 -> 0.2 | K34: ==S34 -> 40400 | L34: ==K34*I34 -> 323200 | O34: 87600（B×H=1.6×2.4m，渠深30m，N=1.5kW） | Q34: 56000（B*H=900*2400m） | R34: ==AVERAGE(X34,AD34,AJ34,AP34) -> 57533.333 | S34: ==MIN(X34,AD34,AJ34,AP34) -> 40400 | T34: 新环环保 | U34: 连皓文13500036502 | V34: 88000 | W34: 0.2 | X34: ==V34*(1-W34) -> 70400 | Y34: ==X34*I34 -> 563200 | Z34: 无锡通用 | AA34: 杨培根18961775586 | AB34: 50500 | AC34: 0.2 | AD34: ==AB34*(1-AC34) -> 40400 | AE34: ==AB34*I34 -> 404000 | AF34: 江苏南通 | AG34: 李向阳 15896274137 | AH34: 61800 | AJ34: ==AH34*(1-AI34) -> 61800 | AK34: ==AH34*I34 -> 494400
A35: 2 | B35: 垃圾斗车 | D35: 容积 1 立方米,与螺旋压榨机配套 | E35: 台 | F35: 1 | G35: 5200 | H35: ==G35*F35 -> 5200 | I35: 1 | J35: ==AC35 -> 0.2 | K35: ==S35 -> 5200 | L35: ==K35*I35 -> 5200 | O35: 6000 | Q35: 5000 | R35: ==AVERAGE(X35,AD35,AJ35,AP35) -> 6466.6667 | S35: ==MIN(X35,AD35,AJ35,AP35) -> 5200 | T35: 新环环保 | U35: 连皓文13500036502 | V35: 8000 | W35: 0.2 | X35: ==V35*(1-W35) -> 6400 | Y35: ==X35*I35 -> 6400 | Z35: 无锡通用 | AA35: 杨培根18961775586 | AB35: 6500 | AC35: 0.2 | AD35: ==AB35*(1-AC35) -> 5200 | AE35: ==AB35*I35 -> 6500 | AF35: 江苏南通 | AG35: 李向阳 15896274137 | AH35: 7800 | AJ35: ==AH35*(1-AI35) -> 7800 | AK35: ==AH35*I35 -> 7800
A36: 三 | B36: 曝气沉砂池
A37: 1 | B37: 进水闸门 | D37: 不锈钢附壁方闸门, B × H=1500mm × 2500mm , N=2.2kW ,带手电一体启闭机 | E37: 套 | F37: 2 | G37: 85600 | H37: ==G37*F37 -> 171200 | I37: 2 | J37: ==AC37 -> 0.2 | K37: ==S37 -> 50800 | L37: ==K37*I37 -> 101600 | O37: 60375（B×H=1.50×1.35m，渠深2m，N=1.5kW） | Q37: 62080（BxH=2000x1500 ） | R37: ==AVERAGE(X37,AD37,AJ37,AP37) -> 85000 | S37: ==MIN(X37,AD37,AJ37,AP37) -> 50800 | T37: 新环环保 | U37: 连皓文13500036502 | V37: 118000 | W37: 0.2 | X37: ==V37*(1-W37) -> 94400 | Y37: ==X37*I37 -> 188800 | Z37: 无锡通用 | AA37: 杨培根18961775586 | AB37: 63500 | AC37: 0.2 | AD37: ==AB37*(1-AC37) -> 50800 | AE37: ==AB37*I37 -> 127000 | AF37: 江苏南通 | AG37: 李向阳 15896274137 | AH37: 109800 | AJ37: ==AH37*(1-AI37) -> 109800 | AK37: ==AH37*I37 -> 219600
A38: 2 | B38: 桥式刮砂机 | D38: 行程 L=22.3m ,宽度 B=4.4m , N=0.75+1.1kW ,水下部件不锈钢 | E38: 套 | F38: 2 | G38: 136200 | H38: ==G38*F38 -> 272400 | I38: 2 | J38: ==W38 -> 0.2 | K38: ==S38 -> 156800 | L38: ==K38*I38 -> 313600 | O38: 975000（15万m3/d） | Q38: 150000（L=18.5m） | R38: ==AVERAGE(X38,AD38,AJ38,AP38) -> 204933.33 | S38: ==MIN(X38,AD38,AJ38,AP38) -> 156800 | T38: 新环环保 | U38: 连皓文13500036502 | V38: 196000 | W38: 0.2 | X38: ==V38*(1-W38) -> 156800 | Y38: ==X38*I38 -> 313600 | Z38: 无锡通用 | AA38: 杨培根18961775586 | AB38: 295000 | AC38: 0.2 | AD38: ==AB38*(1-AC38) -> 236000 | AE38: ==AB38*I38 -> 590000 | AF38: 江苏南通 | AG38: 李向阳 15896274137 | AH38: 222000 | AJ38: ==AH38*(1-AI38) -> 222000 | AK38: ==AH38*I38 -> 444000
A39: 3 | B39: 排砂泵 | D39: Q=12L/s , H=10m , N=0.55kW ,定制设备,含水下吸砂管系统及配件,砂接触部件为耐磨耐腐蚀材质 | E39: 套 | F39: 4 | G39: 29900 | H39: ==G39*F39 -> 119600 | I39: 4 | J39: ==W39 -> 0.2 | K39: ==S39 -> 8000 | L39: ==K39*I39 -> 32000 | Q39: 15000（Q=30m3/h） | R39: ==AVERAGE(X39,AD39,AJ39,AP39) -> 36266.667 | S39: ==MIN(X39,AD39,AJ39,AP39) -> 8000 | T39: 新环环保 | U39: 连皓文13500036502 | V39: 10000 | W39: 0.2 | X39: ==V39*(1-W39) -> 8000 | Y39: ==X39*I39 -> 32000 | Z39: 无锡通用 | AA39: 杨培根18961775586 | AB39: 28500 | AC39: 0.2 | AD39: ==AB39*(1-AC39) -> 22800 | AE39: ==AB39*I39 -> 114000 | AF39: 江苏南通 | AG39: 李向阳 15896274137 | AH39: 78000 | AJ39: ==AH39*(1-AI39) -> 78000 | AK39: ==AH39*I39 -> 312000
A40: 4 | B40: 砂水分离器 | D40: Q=15~20L/s , N=1.5kW ,不锈钢材质 | E40: 套 | F40: 2 | G40: 61300 | H40: ==G40*F40 -> 122600 | I40: 2 | J40: ==W40 -> 0.2 | K40: ==S40 -> 57600 | L40: ==K40*I40 -> 115200 | Q40: 80000 | R40: ==AVERAGE(X40,AD40,AJ40,AP40) -> 74000 | S40: ==MIN(X40,AD40,AJ40,AP40) -> 57600 | T40: 新环环保 | U40: 连皓文13500036502 | V40: 72000 | W40: 0.2 | X40: ==V40*(1-W40) -> 57600 | Y40: ==X40*I40 -> 115200 | Z40: 无锡通用 | AA40: 杨培根18961775586 | AB40: 78000 | AC40: 0.2 | AD40: ==AB40*(1-AC40) -> 62400 | AE40: ==AB40*I40 -> 156000 | AF40: 江苏南通 | AG40: 李向阳 15896274137 | AH40: 102000 | AJ40: ==AH40*(1-AI40) -> 102000 | AK40: ==AH40*I40 -> 204000
...

Sheet 电气专业
A1: 设备价格表（含税）
A2: 单位工程：电气专业
A3: 序号 | B3: 设备名称 | C3: 概算规格、型号 | D3: 施工图预算规格、型号 | E3: 单位 | F3: 数量 | G3: 概算 | I3: 预算数量 | J3: 预算选用价格 | M3: 环城北 | O3: 中部水厂 | Q3: 洛溪水厂(首期) | S3: 南站水厂 | U3: 品牌1 | Y3: 品牌2 | AC3: 品牌3 | AG3: 品牌4
G4: 单价(元) | H4: 合价(元) | J4: 建议下浮率 | K4: 单价（元） | L4: 总价（元） | M4: 单价(元) | N4: 合价(元) | O4: 单价(元) | P4: 合价(元) | Q4: 单价(元) | R4: 合价(元) | S4: 询价均值 | T4: 询价最低价 | U4: 公司名称 | V4: 联系人、联系电话 | W4: 单价（元） | X4: 总价（元） | Y4: 公司名称 | Z4: 联系人、联系电话 | AA4: 单价（元） | AB4: 总价（元） | AC4: 公司名称 | AD4: 联系人、联系电话 | AE4: 单价（元） | AF4: 总价（元） | AG4: 公司名称 | AH4: 联系人、联系电话 | AI4: 单价（元） | AJ4: 总价（元）
B5: 光伏发电 | C5: 31.5KW | D5: 31.5KW | E5: m2 | F5: 194 | G5: ==H5/F5 -> 5154.6392 | H5: ==1000000 -> 1000000 | I5: 194 | J5: 0.8 | K5: ==T5*J5 -> 858.53608 | L5: ==I5*K5 -> 166556 | M5: ==N5/150 -> 1200 | N5: ==180000 -> 180000 | O5: 无 | Q5: 无 | S5: ==AVERAGE(W5,AA5,AE5,AI5) -> 1121.1211 | T5: ==MIN(W5,AA5,AE5,AI5) -> 1073.1701 | U5: 易事特 | V5: 陈焰明13925004039 | W5: ==X5/194 -> 1073.1701 | X5: ==208195 -> 208195 | Y5: 天合光能 | Z5: 马少凯18620931285 | AA5: ==AB5/194 -> 1169.0722 | AB5: ==31.5*7200 -> 226800 | AC5: 博燃环保 | AD5: 齐春军18923836432
B6: 电梯 | C6: 载重1350kg，速度1.75m/s | D6: 载重1350kg，速度1.75m/s | E6: 部 | F6: 3 | G6: ==H6/F6 -> 225149.42 | H6: 675448.26 | I6: 3 | J6: 0.9 | K6: ==T6*J6 -> 282047.53 | L6: ==I6*K6 -> 846142.6 | M6: ==N6/3 -> 291666.67 | N6: ==875000 -> 875000 | O6: ==217738.72/1 -> 217738.72 | P6: 217738.72 | Q6: ==R6/3 -> 131368.91 | R6: 394106.74 | S6: ==AVERAGE(W6,AA6,AE6,AI6) -> 326716.85 | T6: ==MIN(W6,AA6,AE6,AI6) -> 313386.15 | U6: 奥的斯 | V6: 王勇13922471918 | W6: ==X6/I6 -> 340047.55 | X6: 1020142.7 | Y6: 日立 | Z6: 陈总13246889088 | AA6: ==AB6/I6 -> 313386.15 | AB6: 940158.45 | AC6: 三菱 | AD6: 夏林涛13823799205
B7: 高压柜、直流屏 | C7: KYN28-12kV,800x1500x2300(WxDxH) | D7: KYN28-12kV,800x1500x2300(WxDxH) | E7: 台 | F7: 14 | G7: ==H7/F7 -> 50892.743 | H7: ==712498.4 -> 712498.4 | I7: 14 | J7: 1 | K7: ==T7*J7 -> 72087.667 | L7: ==I7*K7 -> 1009227.3 | M7: ==N7/14 -> 101365.71 | N7: ==1419120 -> 1419120 | O7: ==P7/12 -> 49055.342 | P7: ==588664.11 -> 588664.11 | Q7: ==R7/10 -> 100057.6 | R7: ==1000576 -> 1000576 | S7: ==AVERAGE(W7,AA7,AE7,AI7) -> 76261.833 | T7: ==MIN(W7,AA7,AE7,AI7) -> 72087.667 | U7: 颢成电气 | V7: 张总13352866588 | W7: ==X7/12 -> 80436 | X7: ==965232 -> 965232 | Y7: 白云电器 | Z7: 江德州15902087618 | AA7: ==AB7/12 -> 72087.667 | AB7: ==865052 -> 865052 | AC7: 尔安 | AD7: 冯总13424037926
B8: 低压进线柜 | C8: WxDxH=800x1000x2200mm | D8: WxDxH=800x1000x2200mm | E8: 台 | F8: 69 | G8: ==H8/F8 -> 76617.675 | H8: 5286619.5 | I8: 69 | J8: 1 | K8: ==T8*J8 -> 58355.767 | L8: ==I8*K8 -> 4026547.9 | M8: ==N8/150 -> 61126.667 | N8: ==9169000 -> 9169000 | O8: ==P8/63 -> 51633.21 | P8: ==3252892.2 -> 3252892.2 | Q8: ==R8/73 -> 80688.329 | R8: ==5890248 -> 5890248 | S8: ==AVERAGE(W8,AA8,AE8,AI8) -> 64487.123 | T8: ==MIN(W8,AA8,AE8,AI8) -> 58355.767 | U8: 颢成电气 | V8: 张总13352866588 | W8: ==X8/73 -> 58355.767 | X8: 4259971 | Y8: 白云电器 | Z8: 江德州15902087618 | AA8: ==AB8/69 -> 70618.478 | AB8: ==4872675 -> 4872675 | AC8: 尔安 | AD8: 冯总13424037926
B9: 变压器 | C9: SCB17-2500kVA,10kV/0.4kV,Uk=6% | D9: SCB15-2500kVA,10kV/0.4kV,Uk=6% | E9: 台 | F9: 2 | G9: ==H9/F9 -> 218384.01 | H9: 436768.02 | I9: 2 | J9: 0.8 | K9: ==T9*J9 -> 318400 | L9: ==I9*K9 -> 636800 | M9: ==N9/4 -> 200000 | N9: ==800000 -> 800000 | O9: ==P9/2 -> 236283 | P9: ==472566 -> 472566 | Q9: ==R9/3 -> 218900 | R9: ==656700 -> 656700 | S9: ==AVERAGE(W9,AA9,AE9,AI9) -> 399000 | T9: ==MIN(W9,AA9,AE9,AI9) -> 398000 | U9: 特变电工 | V9: 魏龙13380043790 | W9: ==X9/2 -> 398000 | X9: ==796000 -> 796000 | Y9: 明珠 | Z9: 甘经理13928809635 | AA9: ==AB9/2 -> 400000 | AB9: ==800000 -> 800000 | AC9: 广高高压 | AD9: 020-82266589
B10: 固定式柴油发电机组 | C10: 静音型,长行功率1600kW，自带ATS切换柜 | D10: 静音型,长行功率1600kW，自带ATS切换柜 | E10: 台 | F10: 1 | G10: ==H10/F10 -> 1250342.8 | H10: ==1250342.82 -> 1250342.8 | I10: 1 | J10: 0.9 | K10: ==T10*J10 -> 1575000 | L10: ==I10*K10 -> 1575000 | M10: ==N10/1 -> 800000 | N10: ==800000 -> 800000 | O10: ==P10/1 -> 998920 | P10: ==998920 -> 998920 | Q10: 无 | S10: ==AVERAGE(W10,AA10,AE10,AI10) -> 2170940.7 | T10: ==MIN(W10,AA10,AE10,AI10) -> 1750000 | U10: 进口卡特彼勒 | V10: 张总13041675888 | W10: ==X10/1 -> 2580000 | X10: ==2580000 -> 2580000 | Y10: 进口珀金斯 | Z10: 俞经理15985867496 | AA10: ==AB10/1 -> 1750000 | AB10: ==1750000 -> 1750000 | AC10: 进口康明斯 | AD10: 施总13802395095 | AE10: ==AF10/1 -> 2182822 | AF10: ==2182822 -> 2182822

Sheet 仪表自控专业设备
A1: 设备价格表（含税）
A2: 单位工程：仪表自控专业设备
A3: 序号 | B3: 设备名称 | C3: 概算规格、型号 | D3: 施工图预算规格、型号 | E3: 单位 | F3: 数量 | G3: 概算 | I3: 预算数量 | J3: 预算选用价格 | M3: 品牌1 | Q3: 品牌2 | U3: 品牌3 | Y3: 品牌4
G4: 单价(元) | H4: 合价(元) | J4: 建议下浮率 | K4: 单价（元） | L4: 总价（元） | M4: 公司名称 | N4: 联系人、联系电话 | O4: 单价（元） | P4: 总价（元） | Q4: 公司名称 | R4: 联系人、联系电话 | S4: 单价（元） | T4: 总价（元） | U4: 公司名称 | V4: 联系人、联系电话 | W4: 单价（元） | X4: 总价（元） | Y4: 公司名称 | Z4: 联系人、联系电话 | AA4: 单价（元） | AB4: 总价（元）
A5: 一 | B5: 工艺自控系统
B6: 中控室设备
A7: 1 | B7: I/O服务器 | C7: 1.名称:I/O服务器 2.规格:1)双路10核芯Xeon Silver 4210(2.20GHz)处理器;3)内存: 64GB ECC DDR4 RDIMM内存,最大支持640GB; 4)硬盘: 4x2.4TB 2.5" SAS(10K rpm)热插拔硬盘,最大支持16块热插拔硬盘,支持组建RAID0/1/1+0/5/7(本工程组建RAID 1+0); 5)I/O插槽: 1个全长PCI-E x16, 4个全长PCI-E x8和2个全长PCI-E x4插槽; 6)网卡: 双口千/百兆自适应工业以太网卡; 7)显示组件: 独立显卡(显存4GB);22"LCD显示器; 8)操作系统: 预装Windows Server 2019 企业版; 9)服务器机柜(合用): 工业标准,2000Hx1000Wx600D(mm),配22"LCD显示器专用托架,1U键盘托架1个;带鼠标键盘及显示器共享器(KVM转换器):PS/2 KVM接口适配器4口,VGA KVM切换口4个,RS485及RS-232 通讯口各2个; 10)其它: 4U机架式服务器;服务器采用工业标准服务器,电源、CPU、内存、I/O控制组件均采用冗余配置,服务器完全采用单机冗余方式;键盘、鼠标一套;16X DVD+/-RW;带通讯接口转换器:RS-485->PLC现场总线通讯接口; | E7: 套 | F7: 1 | G7: 138600 | H7: 138600 | K7: ==MIN(O7,S7,W7) -> 52800 | L7: ==F7*K7 -> 52800 | N7: 武宝凤 13826219800 | O7: 52800 | P7: ==F7*O7 -> 52800 | Q7: ABB | U7: 西门子 | V7: 张勇勤 18736008728 | W7: 95000 | X7: ==F7*W7 -> 95000
A8: 2 | B8: 监控服务器(组成双机热备服务器) | C8: 1)双路10核芯Xeon Silver 4210(2.20GHz)处理器;3)内存: 64GB ECC DDR4 RDIMM内存,最大支持640GB; 4)硬盘: 4x2.4TB 2.5" SAS(10K rpm)热插拔硬盘,最大支持16块热插拔硬盘,支持组建RAID0/1/1+0/5/7(本工程组建RAID 1+0); 5)I/O插槽: 1个全长PCI-E x16, 4个全长PCI-E x8和2个全长PCI-E x4插槽; 6)网卡: 双口千/百兆自适应工业以太网卡; 7)显示组件: 独立显卡(显存4GB);22"LCD显示器; 8)操作系统: 预装Windows Server 2019 企业版; 9)服务器机柜(合用): 工业标准,2000Hx1000Wx600D(mm),配22"LCD显示器专用托架,1U键盘托架1个;带鼠标键盘及显示器共享器(KVM转换器):PS/2 KVM接口适配器4口,VGA KVM切换口4个,RS485及RS-232 通讯口各2个; 10)其它: 4U机架式服务器;服务器采用工业标准服务器,电源、CPU、内存、I/O控制组件均采用冗余配置,服务器完全采用单机冗余方式;键盘、鼠标一套;16X DVD+/-RW;带通讯接口转换器:RS-485->PLC现场总线通讯接口; | E8: 套 | F8: 1 | G8: 138600 | H8: 138600 | K8: ==MIN(O8,S8,W8) -> 52800 | L8: ==F8*K8 -> 52800 | N8: 武宝凤 13826219800 | O8: 52800 | P8: ==F8*O8 -> 52800 | Q8: ABB | U8: 西门子 | V8: 张勇勤 18736008728 | W8: 95000 | X8: ==F8*W8 -> 95000
A9: 3 | B9: 工业以太网交换机 | C9: 支持工业光纤环以太网(冗余环,全负载状态下自愈时间<20ms);支持VLN功能,支持三层交换,支持流量控制,存储转发,带网管功能 | E9: 套 | F9: 5 | G9: 22000 | H9: 110000 | K9: ==MIN(O9,S9,W9) -> 56038 | L9: ==F9*K9 -> 280190 | N9: 武宝凤 13826219800 | O9: 56038 | P9: ==F9*O9 -> 280190 | Q9: ABB | U9: 西门子 | V9: 张勇勤 18736008728 | W9: 77053 | X9: ==F9*W9 -> 385265
A10: 4 | B10: 不间断电源 | C10: 在线式UPS,输入:380VAC,输出220VAC;10kVA120min备电,功率因数不小于0.98, RS232通讯接口 | E10: 套 | F10: 1 | G10: 38500 | H10: 38500 | K10: ==MIN(O10,S10,W10) -> 24350 | L10: ==F10*K10 -> 24350 | M10: 美国原厂SANTAK | N10: 施扬辉 13459466252 | O10: 24350 | P10: ==F10*O10 -> 24350 | Q10: 美国原厂艾默生Emerson | R10: 张新芬 13425171172 | S10: 37350 | T10: ==F10*S10 -> 37350 | U10: 日本原装APC | V10: 刘经理 15601761158 | W10: 48500 | X10: ==F10*W10 -> 48500 | Y10: 伊顿UPS | AC10: 梅兰日兰
A11: 5 | B11: 大屏幕无缝拼接墙系统(小间距LED拼接显示技术) | C11: 点间距：5.400(L)*1.920(H)=10.368m2;厚度(mm):≤14.50; 推荐最小观看距离≥3.0m; 视角(水平/垂直) ≥170度;屏幕亮度(cd/m2) ≥1000; 扫描驱动方式:1/32 扫描,恒流驱动; | E11: 套 | F11: 1 | G11: 379900 | H11: 379900 | K11: ==MIN(O11,S11,W11) -> 175180 | L11: ==F11*K11 -> 175180 | M11: 广州市炬诚电子科技 | Q11: 雷曼 | U11: 洲明 | W11: 175180 | X11: ==F11*W11 -> 175180
A12: 6 | B12: 便携式复合气体检测仪 | C12: 可充电锂电池供电,外壳防护等级IP67,防爆: 不低于Exd IIBT6;带RS232及USB接口,带95分贝声音报警(可设置多种报警音频);便携式,背光LCD同时显示各通道的气体浓度值,柱状图形显示电量;-10%%DC~+60%%DC; 工作湿度:≤95%RH,无冷凝(湿度>90%RH);测量范围:H2S: 0-100mg/m3; CH4:0-100%LEL; NH3:0-100ppm; O2: 0-25%VOL; | E12: 套 | F12: 2 | K12: ==MIN(O12,S12,W12) -> 28458 | L12: ==F12*K12 -> 56916 | M12: 英思科 | O12: 28458 | P12: ==F12*O12 -> 56916 | Q12: 罗斯蒙特 | U12: 霍尼威尔 | Y12: 科尔康
A13: 二 | B13: 中控室软件
A14: 1 | B14: 上位机软件狗 | C14: 运行版,无限点,软件与PLC实际硬件的一致 | E14: 套 | F14: 3 | G14: 118800 | H14: 356400 | K14: ==MIN(O14,S14,W14) -> 74267.46 | L14: ==F14*K14 -> 222802.38 | U14: 西门子 | V14: 张勇勤 18736008728 | W14: 74267.46 | X14: ==F14*W14 -> 222802.38
A15: 2 | B15: 上位机软件狗 | C15: 开发版+运行版,无限点,软件与PLC实际硬件的一致 | E15: 套 | F15: 1 | G15: 103700 | H15: 103700 | K15: ==MIN(O15,S15,W15) -> 35289.2 | L15: ==F15*K15 -> 35289.2 | U15: 西门子 | V15: 张勇勤 18736008728 | W15: ==16165+38248.4/2 -> 35289.2 | X15: ==F15*W15 -> 35289.2
A16: 3 | B16: 上位机画面开发 | E16: 套 | F16: 1 | G16: 8400 | H16: 8400 | K16: ==MIN(O16,S16,W16) -> 0 | L16: ==F16*K16 -> 0 | W16: 已含于工程师站软件内
A17: 4 | B17: PLC编程软件 | C17: 与PLC硬件系统配套,含编程电缆 | E17: 套 | F17: 1 | G17: 28100 | H17: 28100 | K17: ==MIN(O17,S17,W17) -> 0 | L17: ==F17*K17 -> 0 | W17: 已含于工程师站软件内
A18: 5 | B18: 数据库管理软件 | C18: SQL SERVER 2016企业版 | E18: 套 | F18: 2 | G18: 140732.58 | H18: 281465.16 | K18: ==MIN(O18,S18,W18) -> 53512 | L18: ==F18*K18 -> 107024 | U18: 西门子 | V18: 张勇勤 18736008728 | W18: 53512 | X18: ==F18*W18 -> 107024
A19: 6 | B19: 实时历史数据库管理软件 | C19: Historian实时数据库,用于实时监测数据的记录,60000点授权 | E19: 套 | F19: 1 | G19: 70366.31 | H19: 70366.31 | K19: ==MIN(O19,S19,W19) -> 414103 | L19: ==F19*K19 -> 414103 | U19: 西门子 | V19: 张勇勤 18736008728 | W19: 414103 | X19: ==F19*W19 -> 414103
A20: 7 | B20: 自控系统二次开发 | E20: 套 | F20: 1 | G20: 140732.58 | H20: 140732.58 | K20: ==MIN(O20,S20,W20) -> 0 | L20: ==F20*K20 -> 0
A21: 四 | B21: 网络电话系统设备
A22: 1 | B22: 网络电话机 | C22: 1) VOIP标准, 壁挂式, 防潮型, RJ45接口,PoE供电,IP65; 2) 支持WAN/LAN口桥模式与路由模式的选择,可以同时接入IP语音和数据业务; 3) 基于SIP标准协议,兼容任何采用SIP标准的IP电话系统;支持全部标准PBX功能; 4) 2路来电显示支 持2个同时并存的呼叫;NAT穿透, 支持STUN方式穿透; | E22: 台 | F22: 11 | G22: 20200 | H22: 222200 | K22: ==MIN(O22,S22,W22) -> 250 | L22: ==F22*K22 -> 2750 | M22: 鼎信通达 | N22: 陈玉楼 13825193113 | O22: 260 | P22: ==F22*O22 -> 2860 | Q22: Alcatel阿尔卡特H2 | R22: 谢海锋18620817000 | S22: 250 | T22: ==F22*S22 -> 2750 | U22: 申瓯 | W22: 300 | X22: ==F22*W22 -> 3300
A23: 2 | B23: IP PBX（IP电话网关） | C23: 1) 用户容量最大容量:300(最大224个本地模拟用户/300个IP用户) 2) 终端类型:模拟话机、IP话机、视频话机 3) 中继接口:提供16路FXO、2E1/T1接口 4) 信令协议:SS7、R2、PRI、QSIG、SIP 5) AC:100V~240V;50Hz/60Hz; 6) 标准19英寸2U机框; 7) 可管理性:支持集中/远程设备管理、信令跟踪、资源管理、告警管理、快速开局 | E23: 套 | F23: 1 | G23: 7700 | H23: 7700 | K23: ==MIN(O23,S23,W23) -> 3520 | L23: ==F23*K23 -> 3520 | M23: 星纵 | N23: 陈玉楼 13825193113 | O23: 11680 | P23: ==F23*O23 -> 11680 | Q23: 三汇 | R23: 谢海锋18620817000 | S23: 3520 | T23: ==F23*S23 -> 3520 | U23: 申瓯 | W23: 42000 | X23: ==F23*W23 -> 42000
B24: IP电话交换软件 | C24: 可通过以太网与外线电话、内部IP电话进行呼叫、通话(含电话话费) | E24: 套 | F24: 1 | G24: 6100 | H24: 6100 | M24: 松下 | N24: 含于整体设备 | Q24: 爱立信 | R24: 含于整体设备 | U24: 申瓯 | V24: 含于整体设备
A25: 七 | B25: 地面设备间
A26: 1 | B26: 地面自控室PLC测控站（1PLC站） | C26: 可编程控制器系统(含冗余CPU模块、冗余电源模块、冗余通讯模块)1) 104xDI,32xDO,4xAI,4xAO,I/O隔离,带电源、信号浪涌保护器;2) 支持工业以太网/Profibus/ControlNet/MB+;带工业以太网、工业现场总线通讯接口(注:污水厂全厂PLC自控设备的工业现场总线通讯接口应统一)及 RS485接口,带相关总线通讯适配器;3) 10.4英寸工业用带背光TFT彩色LCD触摸屏(1024x768像素);4) 配套在线式UPS 220VAC 5kVA 120min不间断电源;5) 含导轨式,24电口(不少于4个PoE口),8光口千兆工业以太网PoE交换机(支持光纤环,网管型),防潮型,IP65。6) 含导轨式,8路,485通信管理机。7) 1套PLC机柜2200Hx800Wx1000D(mm),(含PLC程序及触摸屏组态)。 | E26: 套 | F26: 1 | G26: 347050 | H26: 347050 | K26: ==MIN(O26,S26,W26) -> 179000 | L26: ==F26*K26 -> 179000 | N26: 武宝凤 13826219800 | O26: 179000 | P26: ==F26*O26 -> 179000 | Q26: ABB | U26: 西门子 | V26: 张勇勤 18736008728 | W26: 310000 | X26: ==F26*W26 -> 310000 | Y26: 施耐德 | Z26: 李越13826163590
